Workbook
Name 複勝: '⑤の計算式'!$E$3:$F$8
Name 単勝: '②の計算式'!$B$3:$C$8
Name 単勝: '③の計算式'!$B$3:$C$8
Name 単勝: '④の計算式'!$B$3:$C$8
Name 複勝: '③の計算式'!$E$3:$F$8
Name 複勝: '④の計算式'!$E$3:$F$8
Name 単勝: '①の計算式'!$B$3:$C$8
Name 単勝: '⑥の計算式'!$B$3:$C$8
Name 複勝: '⑥の計算式'!$E$3:$F$8
Name 複勝: '②の計算式'!$E$3:$F$8
Name 複勝: '①の計算式'!$E$3:$F$8
Name 単勝: '⑤の計算式'!$B$3:$C$8
Name 結果: '仮オッズ'!$A$17:$B$22

Sheet 仮オッズ
A1: 名前 | B1: ポイント | D1: 単勝オッズ
A2: ゆーや | B2: 19 | D2: =SUM(B2:B7)/B2*A13 -> 2.1052632
A3: たいよう | B3: 17 | D3: =SUM(B2:B7)/B3*A13 -> 2.3529412
A4: はせりょー | B4: 7 | D4: =SUM(B2:B7)/B4*A13 -> 5.7142857
A5: みわ | B5: 3 | D5: =SUM(B2:B7)/B5*A13 -> 13.333333
A6: こーた | B6: 3 | D6: =SUM(B2:B7)/B6*A13 -> 13.333333
A7: いずみ | B7: 1 | D7: =SUM(B2:B7)/B7*A13 -> 40
A8: 未選択
A12: 単勝係数 | B12: 複勝係数
A13: 0.8 | B13: 1
A16: 結果
A17: 一着 | B17: こーた
A18: 二着 | B18: はせりょー
A19: 三着 | B19: みわ
A20: 四着 | B20: いずみ
A21: 五着 | B21: ゆーや
A22: 六着 | B22: たいよう

Sheet ①の計算式
I1: xが1着になる確率
B2: 単勝 | E2: 複勝 | H2: 三連 | I2: p(x)
B3: ='仮オッズ'!A2 -> ゆーや | C3: ='仮オッズ'!D2 -> 2.1052632 | E3: ='仮オッズ'!A2 -> ゆーや | F3: =1/(1-(1-(1/'仮オッズ'!D2))^3) -> 1.1691847 | H3: ='仮オッズ'!A2 -> ゆーや | I3: =1/C3 -> 0.475
B4: ='仮オッズ'!A3 -> たいよう | C4: ='仮オッズ'!D3 -> 2.3529412 | E4: ='仮オッズ'!A3 -> たいよう | F4: =1/(1-(1-(1/'仮オッズ'!D3))^3) -> 1.2347346 | H4: ='仮オッズ'!A3 -> たいよう | I4: =1/C4 -> 0.425
B5: ='仮オッズ'!A4 -> はせりょー | C5: ='仮オッズ'!D4 -> 5.7142857 | E5: ='仮オッズ'!A4 -> はせりょー | F5: =1/(1-(1-(1/'仮オッズ'!D4))^3) -> 2.280583 | H5: ='仮オッズ'!A4 -> はせりょー | I5: =1/C5 -> 0.175
B6: ='仮オッズ'!A5 -> みわ | C6: ='仮オッズ'!D5 -> 13.333333 | E6: ='仮オッズ'!A5 -> みわ | F6: =1/(1-(1-(1/'仮オッズ'!D5))^3) -> 4.795085 | H6: ='仮オッズ'!A5 -> みわ | I6: =1/C6 -> 0.075
B7: ='仮オッズ'!A6 -> こーた | C7: ='仮オッズ'!D6 -> 13.333333 | E7: ='仮オッズ'!A6 -> こーた | F7: =1/(1-(1-(1/'仮オッズ'!D6))^3) -> 4.795085 | H7: ='仮オッズ'!A6 -> こーた | I7: =1/C7 -> 0.075
B8: ='仮オッズ'!A7 -> いずみ | C8: ='仮オッズ'!D7 -> 40 | E8: ='仮オッズ'!A7 -> いずみ | F8: =1/(1-(1-(1/'仮オッズ'!D7))^3) -> 13.672292 | H8: ='仮オッズ'!A7 -> いずみ | I8: =1/C8 -> 0.025
B9: ='仮オッズ'!A8 -> 未選択 | C9: ='仮オッズ'!D8 | E9: ='仮オッズ'!A8 -> 未選択 | H9: ='仮オッズ'!A8 -> 未選択
B10: ='仮オッズ'!A9 | C10: ='仮オッズ'!D9:D18 | E10: ='仮オッズ'!A9 | H10: ='仮オッズ'!A9
B11: ='仮オッズ'!A10 | E11: ='仮オッズ'!A10 | H11: ='仮オッズ'!A10
B12: 3列目 | F12: 三連
F13: =IFS('A馬券購入'!B3='仮オッズ'!$A$2,$I$3,'A馬券購入'!B3='仮オッズ'!$A$3,$I$4,'A馬券購入'!B3='仮オッズ'!$A$4,$I$5,'A馬券購入'!B3='仮オッズ'!$A$5,$I$6,'A馬券購入'!B3='仮オッズ'!$A$6,$I$7,'A馬券購入'!B3='仮オッズ'!$A$7,$I$8) -> 0.025 | G13: =IFS('A馬券購入'!C3='仮オッズ'!$A$2,$I$3,'A馬券購入'!C3='仮オッズ'!$A$3,$I$4,'A馬券購入'!C3='仮オッズ'!$A$4,$I$5,'A馬券購入'!C3='仮オッズ'!$A$5,$I$6,'A馬券購入'!C3='仮オッズ'!$A$6,$I$7,'A馬券購入'!C3='仮オッズ'!$A$7,$I$8) -> #N/A | H13: =IFS('A馬券購入'!D3='仮オッズ'!$A$2,$I$3,'A馬券購入'!D3='仮オッズ'!$A$3,$I$4,'A馬券購入'!D3='仮オッズ'!$A$4,$I$5,'A馬券購入'!D3='仮オッズ'!$A$5,$I$6,'A馬券購入'!D3='仮オッズ'!$A$6,$I$7,'A馬券購入'!D3='仮オッズ'!$A$7,$I$8) -> #N/A
A14: 単勝 | B14: =VLOOKUP('A馬券購入'!B$3,単勝,2,false) -> 40 | F14: =IFS('A馬券購入'!B4='仮オッズ'!$A$2,$I$3,'A馬券購入'!B4='仮オッズ'!$A$3,$I$4,'A馬券購入'!B4='仮オッズ'!$A$4,$I$5,'A馬券購入'!B4='仮オッズ'!$A$5,$I$6,'A馬券購入'!B4='仮オッズ'!$A$6,$I$7,'A馬券購入'!B4='仮オッズ'!$A$7,$I$8) -> #N/A | G14: =IFS('A馬券購入'!C4='仮オッズ'!$A$2,$I$3,'A馬券購入'!C4='仮オッズ'!$A$3,$I$4,'A馬券購入'!C4='仮オッズ'!$A$4,$I$5,'A馬券購入'!C4='仮オッズ'!$A$5,$I$6,'A馬券購入'!C4='仮オッズ'!$A$6,$I$7,'A馬券購入'!C4='仮オッズ'!$A$7,$I$8) -> 0.425 | H14: =IFS('A馬券購入'!D4='仮オッズ'!$A$2,$I$3,'A馬券購入'!D4='仮オッズ'!$A$3,$I$4,'A馬券購入'!D4='仮オッズ'!$A$4,$I$5,'A馬券購入'!D4='仮オッズ'!$A$5,$I$6,'A馬券購入'!D4='仮オッズ'!$A$6,$I$7,'A馬券購入'!D4='仮オッズ'!$A$7,$I$8) -> 0.075
A15: 複勝 | B15: =VLOOKUP('A馬券購入'!B3,複勝,2,false) -> 13.672292 | F15: =IFS('A馬券購入'!B5='仮オッズ'!$A$2,$I$3,'A馬券購入'!B5='仮オッズ'!$A$3,$I$4,'A馬券購入'!B5='仮オッズ'!$A$4,$I$5,'A馬券購入'!B5='仮オッズ'!$A$5,$I$6,'A馬券購入'!B5='仮オッズ'!$A$6,$I$7,'A馬券購入'!B5='仮オッズ'!$A$7,$I$8) -> #N/A | G15: =IFS('A馬券購入'!C5='仮オッズ'!$A$2,$I$3,'A馬券購入'!C5='仮オッズ'!$A$3,$I$4,'A馬券購入'!C5='仮オッズ'!$A$4,$I$5,'A馬券購入'!C5='仮オッズ'!$A$5,$I$6,'A馬券購入'!C5='仮オッズ'!$A$6,$I$7,'A馬券購入'!C5='仮オッズ'!$A$7,$I$8) -> #N/A | H15: =IFS('A馬券購入'!D5='仮オッズ'!$A$2,$I$3,'A馬券購入'!D5='仮オッズ'!$A$3,$I$4,'A馬券購入'!D5='仮オッズ'!$A$4,$I$5,'A馬券購入'!D5='仮オッズ'!$A$5,$I$6,'A馬券購入'!D5='仮オッズ'!$A$6,$I$7,'A馬券購入'!D5='仮オッズ'!$A$7,$I$8) -> #N/A
A16: 三連単 | B16: =1/((F13*(G13/(1-F13))*(H13/(1-F13-G13)))) -> #N/A | F16: =IFS('A馬券購入'!B6='仮オッズ'!$A$2,$I$3,'A馬券購入'!B6='仮オッズ'!$A$3,$I$4,'A馬券購入'!B6='仮オッズ'!$A$4,$I$5,'A馬券購入'!B6='仮オッズ'!$A$5,$I$6,'A馬券購入'!B6='仮オッズ'!$A$6,$I$7,'A馬券購入'!B6='仮オッズ'!$A$7,$I$8) -> #N/A | G16: =IFS('A馬券購入'!C6='仮オッズ'!$A$2,$I$3,'A馬券購入'!C6='仮オッズ'!$A$3,$I$4,'A馬券購入'!C6='仮オッズ'!$A$4,$I$5,'A馬券購入'!C6='仮オッズ'!$A$5,$I$6,'A馬券購入'!C6='仮オッズ'!$A$6,$I$7,'A馬券購入'!C6='仮オッズ'!$A$7,$I$8) -> #N/A | H16: =IFS('A馬券購入'!D6='仮オッズ'!$A$2,$I$3,'A馬券購入'!D6='仮オッズ'!$A$3,$I$4,'A馬券購入'!D6='仮オッズ'!$A$4,$I$5,'A馬券購入'!D6='仮オッズ'!$A$5,$I$6,'A馬券購入'!D6='仮オッズ'!$A$6,$I$7,'A馬券購入'!D6='仮オッズ'!$A$7,$I$8) -> #N/A
A17: 三連複 | B17: =1/(F13*(G13/(1-F13))*(H13/(1-F13-G13))+F13*(H13/(1-F13))*(G13/(1-F13-H13))+G13*(F13/(1-G13))*(H13/(1-F13-G13))+G13*(H13/(1-G13))*(F13/(1-G13-H13))+H13*(F13/(1-H13))*(G13/(1-H13-F13))+H13*(G13/(1-H13))*(F13/(1-G13-F13))) -> #N/A | F17: =IFS('A馬券購入'!B7='仮オッズ'!$A$2,$I$3,'A馬券購入'!B7='仮オッズ'!$A$3,$I$4,'A馬券購入'!B7='仮オッズ'!$A$4,$I$5,'A馬券購入'!B7='仮オッズ'!$A$5,$I$6,'A馬券購入'!B7='仮オッズ'!$A$6,$I$7,'A馬券購入'!B7='仮オッズ'!$A$7,$I$8) -> #N/A | G17: =IFS('A馬券購入'!C7='仮オッズ'!$A$2,$I$3,'A馬券購入'!C7='仮オッズ'!$A$3,$I$4,'A馬券購入'!C7='仮オッズ'!$A$4,$I$5,'A馬券購入'!C7='仮オッズ'!$A$5,$I$6,'A馬券購入'!C7='仮オッズ'!$A$6,$I$7,'A馬券購入'!C7='仮オッズ'!$A$7,$I$8) -> #N/A | H17: =IFS('A馬券購入'!D7='仮オッズ'!$A$2,$I$3,'A馬券購入'!D7='仮オッズ'!$A$3,$I$4,'A馬券購入'!D7='仮オッズ'!$A$4,$I$5,'A馬券購入'!D7='仮オッズ'!$A$5,$I$6,'A馬券購入'!D7='仮オッズ'!$A$6,$I$7,'A馬券購入'!D7='仮オッズ'!$A$7,$I$8) -> #N/A
F18: =IFS('A馬券購入'!B8='仮オッズ'!$A$2,$I$3,'A馬券購入'!B8='仮オッズ'!$A$3,$I$4,'A馬券購入'!B8='仮オッズ'!$A$4,$I$5,'A馬券購入'!B8='仮オッズ'!$A$5,$I$6,'A馬券購入'!B8='仮オッズ'!$A$6,$I$7,'A馬券購入'!B8='仮オッズ'!$A$7,$I$8) -> #N/A | G18: =IFS('A馬券購入'!C8='仮オッズ'!$A$2,$I$3,'A馬券購入'!C8='仮オッズ'!$A$3,$I$4,'A馬券購入'!C8='仮オッズ'!$A$4,$I$5,'A馬券購入'!C8='仮オッズ'!$A$5,$I$6,'A馬券購入'!C8='仮オッズ'!$A$6,$I$7,'A馬券購入'!C8='仮オッズ'!$A$7,$I$8) -> #N/A | H18: =IFS('A馬券購入'!D8='仮オッズ'!$A$2,$I$3,'A馬券購入'!D8='仮オッズ'!$A$3,$I$4,'A馬券購入'!D8='仮オッズ'!$A$4,$I$5,'A馬券購入'!D8='仮オッズ'!$A$5,$I$6,'A馬券購入'!D8='仮オッズ'!$A$6,$I$7,'A馬券購入'!D8='仮オッズ'!$A$7,$I$8) -> #N/A
B19: 計算した値 | C19: 1.1の調整 | D19: 表示する値 | F19: =IFS('A馬券購入'!B9='仮オッズ'!$A$2,$I$3,'A馬券購入'!B9='仮オッズ'!$A$3,$I$4,'A馬券購入'!B9='仮オッズ'!$A$4,$I$5,'A馬券購入'!B9='仮オッズ'!$A$5,$I$6,'A馬券購入'!B9='仮オッズ'!$A$6,$I$7,'A馬券購入'!B9='仮オッズ'!$A$7,$I$8) -> #N/A | G19: =IFS('A馬券購入'!C9='仮オッズ'!$A$2,$I$3,'A馬券購入'!C9='仮オッズ'!$A$3,$I$4,'A馬券購入'!C9='仮オッズ'!$A$4,$I$5,'A馬券購入'!C9='仮オッズ'!$A$5,$I$6,'A馬券購入'!C9='仮オッズ'!$A$6,$I$7,'A馬券購入'!C9='仮オッズ'!$A$7,$I$8) -> #N/A | H19: =IFS('A馬券購入'!D9='仮オッズ'!$A$2,$I$3,'A馬券購入'!D9='仮オッズ'!$A$3,$I$4,'A馬券購入'!D9='仮オッズ'!$A$4,$I$5,'A馬券購入'!D9='仮オッズ'!$A$5,$I$6,'A馬券購入'!D9='仮オッズ'!$A$6,$I$7,'A馬券購入'!D9='仮オッズ'!$A$7,$I$8) -> #N/A
A20: 3列目 | B20: =IFS('A馬券購入'!A3="単勝",$B$14,'A馬券購入'!A3="複勝",$B$15,'A馬券購入'!A3="三連単",$B$16,'A馬券購入'!A3="三連複",$B$17) -> 13.672292 | C20: =IF(B20<1.1,1.1,B20) -> 13.672292 | D20: =IFERROR(C20,"未選択") -> 13.672292
A21: 4列目 | B21: =IFS('A馬券購入'!A4="単勝",$G$22,'A馬券購入'!A4="複勝",$G$23,'A馬券購入'!A4="三連単",$G$24,'A馬券購入'!A4="三連複",$G$25) -> #N/A | C21: =IF(B21<1.1,1.1,B21) -> #N/A | D21: =IFERROR(C21,"未選択") -> 未選択 | F21: ４列目 | G21: オッズ | H21: 的・不的 | I21: ５列目 | K21: 的・不的 | L21: ６列目 | O21: 7列目
A22: 5列目 | B22: =IFS('A馬券購入'!A5="単勝",$J$22,'A馬券購入'!A5="複勝",$J$23,'A馬券購入'!A5="三連単",$J$24,'A馬券購入'!A5="三連複",$J$25) -> #N/A | C22: =IF(B22<1.1,1.1,B22) -> #N/A | D22: =IFERROR(C22,"未選択") -> 未選択 | F22: 単勝 | G22: =VLOOKUP('A馬券購入'!B$4,単勝,2,false) -> #N/A | H22: =IF('A馬券購入'!B4='仮オッズ'!$B$17,"的中","不的中") -> 不的中 | I22: 単勝 | J22: =VLOOKUP('A馬券購入'!$B$5,単勝,2,false) -> #N/A | K22: =IF('A馬券購入'!B5='仮オッズ'!$B$17,"的中","不的中") -> 不的中 | L22: 単勝 | M22: =VLOOKUP('A馬券購入'!$B$6,単勝,2,false) -> #N/A | N22: =IF('A馬券購入'!B6='仮オッズ'!$B$17,"的中","不的中") -> 不的中 | O22: 単勝 | P22: =VLOOKUP('A馬券購入'!$B$7,単勝,2,false) -> #N/A | Q22: =IF('A馬券購入'!B7='仮オッズ'!$B$17,"的中","不的中") -> 不的中
A23: ６列目 | B23: =IFS('A馬券購入'!A6="単勝",$M$22,'A馬券購入'!A6="複勝",$M$23,'A馬券購入'!A6="三連単",$M$24,'A馬券購入'!A6="三連複",$M$25) -> #N/A | C23: =IF(B23<1.1,1.1,B23) -> #N/A | D23: =IFERROR(C23,"未選択") -> 未選択 | F23: 複勝 | G23: =VLOOKUP('A馬券購入'!$B$4,複勝,2,false) -> #N/A | H23: =IF(OR('A馬券購入'!B4='仮オッズ'!$B$17,'A馬券購入'!B4='仮オッズ'!$B$18,'A馬券購入'!B4='仮オッズ'!$B$19),"的中","不的中") -> 不的中 | I23: 複勝 | J23: =VLOOKUP('A馬券購入'!$B$5,複勝,2,false) -> #N/A | K23: =IF(OR('A馬券購入'!B5='仮オッズ'!$B$17,'A馬券購入'!B5='仮オッズ'!$B$18,'A馬券購入'!B5='仮オッズ'!$B$19),"的中","不的中") -> 不的中 | L23: 複勝 | M23: =VLOOKUP('A馬券購入'!$B$6,複勝,2,false) -> #N/A | N23: =IF(OR('A馬券購入'!B6='仮オッズ'!$B$17,'A馬券購入'!B6='仮オッズ'!$B$18,'A馬券購入'!B6='仮オッズ'!$B$19),"的中","不的中") -> 不的中 | O23: 複勝 | P23: =VLOOKUP('A馬券購入'!$B$7,複勝,2,false) -> #N/A | Q23: =IF(OR('A馬券購入'!B7='仮オッズ'!$B$17,'A馬券購入'!B7='仮オッズ'!$B$18,'A馬券購入'!B7='仮オッズ'!$B$19),"的中","不的中") -> 不的中
A24: 7列目 | B24: =IFS('A馬券購入'!A7="単勝",$P$22,'A馬券購入'!A7="複勝",$P$23,'A馬券購入'!A7="三連単",$P$24,'A馬券購入'!A7="三連複",$P$25) -> #N/A | C24: =IF(B24<1.1,1.1,B24) -> #N/A | D24: =IFERROR(C24,"未選択") -> 未選択 | F24: 三連単 | G24: =1/((F14*(G14/(1-F14))*(H14/(1-F14-G14)))) -> #N/A | H24: =if(AND('A馬券購入'!B4='仮オッズ'!$B$17,'A馬券購入'!C4='仮オッズ'!$B$18,'A馬券購入'!D4='仮オッズ'!$B$19),"的中","不的中") -> 不的中 | I24: 三連単 | J24: =1/((F15*(G15/(1-F15))*(H15/(1-F15-G15)))) -> #N/A | K24: =if(AND('A馬券購入'!B5='仮オッズ'!$B$17,'A馬券購入'!C5='仮オッズ'!$B$18,'A馬券購入'!D5='仮オッズ'!$B$19),"的中","不的中") -> 不的中 | L24: 三連単 | M24: =1/((F16*(G16/(1-F16))*(H16/(1-F16-G16)))) -> #N/A | N24: =if(AND('A馬券購入'!B6='仮オッズ'!$B$17,'A馬券購入'!C6='仮オッズ'!$B$18,'A馬券購入'!D6='仮オッズ'!$B$19),"的中","不的中") -> 不的中 | O24: 三連単 | P24: =1/((F17*(G17/(1-F17))*(H17/(1-F17-G17)))) -> #N/A | Q24: =if(AND('A馬券購入'!B7='仮オッズ'!$B$17,'A馬券購入'!C7='仮オッズ'!$B$18,'A馬券購入'!D7='仮オッズ'!$B$19),"的中","不的中") -> 不的中
F25: 三連複 | G25: =1/(F14*(G14/(1-F14))*(H14/(1-F14-G14))+F14*(H14/(1-F14))*(G14/(1-F14-H14))+G14*(F14/(1-G14))*(H14/(1-F14-G14))+G14*(H14/(1-G14))*(F14/(1-G14-H14))+H14*(F14/(1-H14))*(G14/(1-H14-F14))+H14*(G14/(1-H14))*(F14/(1-G14-F14))) -> #N/A | H25: =IF(AND(OR('仮オッズ'!$B$17='A馬券購入'!B4,'仮オッズ'!$B$18='A馬券購入'!B4,'仮オッズ'!$B$19='A馬券購入'!B4),OR('仮オッズ'!$B$17='A馬券購入'!C4,'仮オッズ'!$B$18='A馬券購入'!C4,'仮オッズ'!$B$19='A馬券購入'!C4),OR('仮オッズ'!$B$17='A馬券購入'!D4,'仮オッズ'!$B$18='A馬券購入'!D4,'仮オッズ'!$B$19='A馬券購入'!D4)),"的中","不的中") -> 不的中 | I25: 三連複 | J25: =1/(F15*(G15*(1-F15))*(H15/(1-F15-G15))+F15*(H15/(1-F15))*(G15/(1-F15-H15))+G15*(F15/(1-G15))*(H15/(1-F15-G15))+G15*(H15/(1-G15))*(F15/(1-G15-H15))+H15*(F15/(1-H15))*(G15/(1-H15-F15))+H15*(G15/(1-H15))*(F15/(1-G15-F15))) -> #N/A | K25: =IF(AND(OR('仮オッズ'!$B$17='A馬券購入'!B5,'仮オッズ'!$B$18='A馬券購入'!B5,'仮オッズ'!$B$19='A馬券購入'!B5),OR('仮オッズ'!$B$17='A馬券購入'!C5,'仮オッズ'!$B$18='A馬券購入'!C5,'仮オッズ'!$B$19='A馬券購入'!C5),OR('仮オッズ'!$B$17='A馬券購入'!D5,'仮オッズ'!$B$18='A馬券購入'!D5,'仮オッズ'!$B$19='A馬券購入'!D5)),"的中","不的中") -> 不的中 | L25: 三連複 | M25: =1/(F16*(G16*(1-F16))*(H16/(1-F16-G16))+F16*(H16/(1-F16))*(G16/(1-F16-H16))+G16*(F16/(1-G16))*(H16/(1-F16-G16))+G16*(H16/(1-G16))*(F16/(1-G16-H16))+H16*(F16/(1-H16))*(G16/(1-H16-F16))+H16*(G16/(1-H16))*(F16/(1-G16-F16))) -> #N/A | N25: =IF(AND(OR('仮オッズ'!$B$17='A馬券購入'!B6,'仮オッズ'!$B$18='A馬券購入'!B6,'仮オッズ'!$B$19='A馬券購入'!B6),OR('仮オッズ'!$B$17='A馬券購入'!C6,'仮オッズ'!$B$18='A馬券購入'!C6,'仮オッズ'!$B$19='A馬券購入'!C6),OR('仮オッズ'!$B$17='A馬券購入'!D6,'仮オッズ'!$B$18='A馬券購入'!D6,'仮オッズ'!$B$19='A馬券購入'!D6)),"的中","不的中") -> 不的中 | O25: 三連複 | P25: =1/(F17*(G17*(1-F17))*(H17/(1-F17-G17))+F17*(H17/(1-F17))*(G17/(1-F17-H17))+G17*(F17/(1-G17))*(H17/(1-F17-G17))+G17*(H17/(1-G17))*(F17/(1-G17-H17))+H17*(F17/(1-H17))*(G17/(1-H17-F17))+H17*(G17/(1-H17))*(F17/(1-G17-F17))) -> #N/A | Q25: =IF(AND(OR('仮オッズ'!$B$17='A馬券購入'!B7,'仮オッズ'!$B$18='A馬券購入'!B7,'仮オッズ'!$B$19='A馬券購入'!B7),OR('仮オッズ'!$B$17='A馬券購入'!C7,'仮オッズ'!$B$18='A馬券購入'!C7,'仮オッズ'!$B$19='A馬券購入'!C7),OR('仮オッズ'!$B$17='A馬券購入'!D7,'仮オッズ'!$B$18='A馬券購入'!D7,'仮オッズ'!$B$19='A馬券購入'!D7)),"的中","不的中") -> 不的中
B27: ３列目
B28: 単勝の時 | C28: =IF('A馬券購入'!B3='仮オッズ'!$B$17,"的中","不的中") -> 不的中
B29: 三連単の時 | C29: =if(AND('A馬券購入'!B3='仮オッズ'!$B$17,'A馬券購入'!C3='仮オッズ'!$B$18,'A馬券購入'!D3='仮オッズ'!$B$19),"的中","不的中") -> 不的中
B30: 複勝のとき | C30: =IF(OR('A馬券購入'!B3='仮オッズ'!$B$17,'A馬券購入'!B3='仮オッズ'!$B$18,'A馬券購入'!B3='仮オッズ'!$B$19),"的中","不的中") -> 不的中
B31: 三連複のとき | C31: =IF(AND(OR('仮オッズ'!$B$17='A馬券購入'!B3,'仮オッズ'!$B$18='A馬券購入'!B3,'仮オッズ'!$B$19='A馬券購入'!B3),OR('仮オッズ'!$B$17='A馬券購入'!C3,'仮オッズ'!$B$18='A馬券購入'!C3,'仮オッズ'!$B$19='A馬券購入'!C3),OR('仮オッズ'!$B$17='A馬券購入'!D3,'仮オッズ'!$B$18='A馬券購入'!D3,'仮オッズ'!$B$19='A馬券購入'!D3)),"的中","不的中") -> 不的中
B34: 表示する値 | C34: 当選金額 | F34: 合計金額
A35: 3列目 | B35: =IFS('A馬券購入'!A3="単勝",$C$28,'A馬券購入'!A3="三連単",$C$29,'A馬券購入'!A3="複勝",$C$30,'A馬券購入'!A3="三連複",$C$31,'A馬券購入'!A3="未選択","×") -> 不的中 | C35: =IFS(B35="的中",'A馬券購入'!E3*'A馬券購入'!F3,B35="不的中",0,B35="×",0) -> 0 | F35: =CEILING(SUM(C35:C39),5) -> 0
A36: 4列目 | B36: =IFS('A馬券購入'!A4="単勝",$H$22,'A馬券購入'!A4="三連単",$H$24,'A馬券購入'!A4="複勝",$H$23,'A馬券購入'!A4="三連複",$H$25,'A馬券購入'!A4="未選択","×") -> 不的中 | C36: =IFS(B36="的中",'A馬券購入'!E4*'A馬券購入'!F4,B36="不的中",0,B36="×",0) -> 0
A37: 5列目 | B37: =IFS('A馬券購入'!A5="単勝",$K$22,'A馬券購入'!A5="三連単",$K$24,'A馬券購入'!A5="複勝",$K$23,'A馬券購入'!A5="三連複",$K$25,'A馬券購入'!A5="未選択","×") -> × | C37: =IFS(B37="的中",'A馬券購入'!E5*'A馬券購入'!F5,B37="不的中",0,B37="×",0) -> 0
A38: ６列目 | B38: =IFS('A馬券購入'!A6="単勝",$N$22,'A馬券購入'!A6="三連単",$N$24,'A馬券購入'!A6="複勝",$N$23,'A馬券購入'!A6="三連複",$N$25,'A馬券購入'!A6="未選択","×") -> × | C38: =IFS(B38="的中",'A馬券購入'!E6*'A馬券購入'!F6,B38="不的中",0,B38="×",0) -> 0
A39: 7列目 | B39: =IFS('A馬券購入'!A7="単勝",$Q$22,'A馬券購入'!A7="三連単",$Q$24,'A馬券購入'!A7="複勝",$Q$23,'A馬券購入'!A7="三連複",$Q$25,'A馬券購入'!A7="未選択","×") -> × | C39: =IFS(B39="的中",'A馬券購入'!E7*'A馬券購入'!F7,B39="不的中",0,B39="×",0) -> 0

Sheet A馬券購入
A2: 券種 | B2: 賭ける人 | E2: 賭けPt | F2: オッズ | G2: 的・不的 | H2: 合計賭け金
A3: 複勝 | B3: いずみ | C3: 未選択 | D3: 未選択 | E3: 2195 | F3: ='①の計算式'!D20 -> 13.672292 | G3: =IF(COUNTIF('仮オッズ'!$A$17:$B$22,"未選択")>0,"×",'①の計算式'!B35) -> 不的中 | H3: =SUM(E3:E7) -> 2195
A4: 三連単 | B4: まりん | C4: たいよう | D4: こーた | E4: 0 | F4: ='①の計算式'!D21 -> 未選択 | G4: =IF(COUNTIF('仮オッズ'!$A$17:$B$22,"未選択")>0,"×",'①の計算式'!B36) -> 不的中 | H4: 払い戻し金
A5: 未選択 | B5: あんじゅ | C5: 未選択 | D5: 未選択 | E5: 0 | F5: ='①の計算式'!D22 -> 未選択 | G5: =IF(COUNTIF('仮オッズ'!$A$17:$B$22,"未選択")>0,"×",'①の計算式'!B37) -> × | H5: =IF(COUNTIF('仮オッズ'!$B$17:$B$22,"未選択")>0,"×",'①の計算式'!F35) -> 0
A6: 未選択 | B6: DDD | C6: 未選択 | D6: 未選択 | E6: 0 | F6: ='①の計算式'!D23 -> 未選択 | G6: =IF(COUNTIF('仮オッズ'!$A$17:$B$22,"未選択")>0,"×",'①の計算式'!B38) -> × | H6: 収支
A7: 未選択 | B7: 平川 | C7: あおい | D7: TOKI | E7: 0 | F7: ='①の計算式'!D24 -> 未選択 | G7: =IF(COUNTIF('仮オッズ'!$A$17:$B$22,"未選択")>0,"×",'①の計算式'!B39) -> × | H7: =IF(H5="×","×",H5-H3) -> -2195

Sheet ②の計算式
I1: xが1着になる確率
B2: 単勝 | E2: 複勝 | H2: 三連 | I2: p(x)
B3: ='仮オッズ'!A2 -> ゆーや | C3: ='仮オッズ'!D2 -> 2.1052632 | E3: ='仮オッズ'!A2 -> ゆーや | F3: =1/(1-(1-(1/'仮オッズ'!D2))^3) -> 1.1691847 | H3: ='仮オッズ'!A2 -> ゆーや | I3: =1/C3 -> 0.475
B4: ='仮オッズ'!A3 -> たいよう | C4: ='仮オッズ'!D3 -> 2.3529412 | E4: ='仮オッズ'!A3 -> たいよう | F4: =1/(1-(1-(1/'仮オッズ'!D3))^3) -> 1.2347346 | H4: ='仮オッズ'!A3 -> たいよう | I4: =1/C4 -> 0.425
B5: ='仮オッズ'!A4 -> はせりょー | C5: ='仮オッズ'!D4 -> 5.7142857 | E5: ='仮オッズ'!A4 -> はせりょー | F5: =1/(1-(1-(1/'仮オッズ'!D4))^3) -> 2.280583 | H5: ='仮オッズ'!A4 -> はせりょー | I5: =1/C5 -> 0.175
B6: ='仮オッズ'!A5 -> みわ | C6: ='仮オッズ'!D5 -> 13.333333 | E6: ='仮オッズ'!A5 -> みわ | F6: =1/(1-(1-(1/'仮オッズ'!D5))^3) -> 4.795085 | H6: ='仮オッズ'!A5 -> みわ | I6: =1/C6 -> 0.075
B7: ='仮オッズ'!A6 -> こーた | C7: ='仮オッズ'!D6 -> 13.333333 | E7: ='仮オッズ'!A6 -> こーた | F7: =1/(1-(1-(1/'仮オッズ'!D6))^3) -> 4.795085 | H7: ='仮オッズ'!A6 -> こーた | I7: =1/C7 -> 0.075
B8: ='仮オッズ'!A7 -> いずみ | C8: ='仮オッズ'!D7 -> 40 | E8: ='仮オッズ'!A7 -> いずみ | F8: =1/(1-(1-(1/'仮オッズ'!D7))^3) -> 13.672292 | H8: ='仮オッズ'!A7 -> いずみ | I8: =1/C8 -> 0.025
B9: ='仮オッズ'!A8 -> 未選択 | C9: ='仮オッズ'!D8 | E9: ='仮オッズ'!A8 -> 未選択 | H9: ='仮オッズ'!A8 -> 未選択
B10: ='仮オッズ'!A9 | C10: ='仮オッズ'!D9:D18 | E10: ='仮オッズ'!A9 | H10: ='仮オッズ'!A9
B11: ='仮オッズ'!A10 | E11: ='仮オッズ'!A10 | H11: ='仮オッズ'!A10
B12: 3列目 | F12: 三連
F13: =IFS('B馬券購入'!B3='仮オッズ'!$A$2,$I$3,'B馬券購入'!B3='仮オッズ'!$A$3,$I$4,'B馬券購入'!B3='仮オッズ'!$A$4,$I$5,'B馬券購入'!B3='仮オッズ'!$A$5,$I$6,'B馬券購入'!B3='仮オッズ'!$A$6,$I$7,'B馬券購入'!B3='仮オッズ'!$A$7,$I$8) -> 0.075 | G13: =IFS('B馬券購入'!C3='仮オッズ'!$A$2,$I$3,'B馬券購入'!C3='仮オッズ'!$A$3,$I$4,'B馬券購入'!C3='仮オッズ'!$A$4,$I$5,'B馬券購入'!C3='仮オッズ'!$A$5,$I$6,'B馬券購入'!C3='仮オッズ'!$A$6,$I$7,'B馬券購入'!C3='仮オッズ'!$A$7,$I$8) -> 0.025 | H13: =IFS('B馬券購入'!D3='仮オッズ'!$A$2,$I$3,'B馬券購入'!D3='仮オッズ'!$A$3,$I$4,'B馬券購入'!D3='仮オッズ'!$A$4,$I$5,'B馬券購入'!D3='仮オッズ'!$A$5,$I$6,'B馬券購入'!D3='仮オッズ'!$A$6,$I$7,'B馬券購入'!D3='仮オッズ'!$A$7,$I$8) -> 0.175
A14: 単勝 | B14: =VLOOKUP('B馬券購入'!B$3,'②の計算式'!単勝,2,false) -> 13.333333 | F14: =IFS('B馬券購入'!B4='仮オッズ'!$A$2,$I$3,'B馬券購入'!B4='仮オッズ'!$A$3,$I$4,'B馬券購入'!B4='仮オッズ'!$A$4,$I$5,'B馬券購入'!B4='仮オッズ'!$A$5,$I$6,'B馬券購入'!B4='仮オッズ'!$A$6,$I$7,'B馬券購入'!B4='仮オッズ'!$A$7,$I$8) -> 0.175 | G14: =IFS('B馬券購入'!C4='仮オッズ'!$A$2,$I$3,'B馬券購入'!C4='仮オッズ'!$A$3,$I$4,'B馬券購入'!C4='仮オッズ'!$A$4,$I$5,'B馬券購入'!C4='仮オッズ'!$A$5,$I$6,'B馬券購入'!C4='仮オッズ'!$A$6,$I$7,'B馬券購入'!C4='仮オッズ'!$A$7,$I$8) -> 0.025 | H14: =IFS('B馬券購入'!D4='仮オッズ'!$A$2,$I$3,'B馬券購入'!D4='仮オッズ'!$A$3,$I$4,'B馬券購入'!D4='仮オッズ'!$A$4,$I$5,'B馬券購入'!D4='仮オッズ'!$A$5,$I$6,'B馬券購入'!D4='仮オッズ'!$A$6,$I$7,'B馬券購入'!D4='仮オッズ'!$A$7,$I$8) -> 0.075
A15: 複勝 | B15: =VLOOKUP('B馬券購入'!B3,'②の計算式'!複勝,2,false) -> 4.795085 | F15: =IFS('B馬券購入'!B5='仮オッズ'!$A$2,$I$3,'B馬券購入'!B5='仮オッズ'!$A$3,$I$4,'B馬券購入'!B5='仮オッズ'!$A$4,$I$5,'B馬券購入'!B5='仮オッズ'!$A$5,$I$6,'B馬券購入'!B5='仮オッズ'!$A$6,$I$7,'B馬券購入'!B5='仮オッズ'!$A$7,$I$8) -> 0.075 | G15: =IFS('B馬券購入'!C5='仮オッズ'!$A$2,$I$3,'B馬券購入'!C5='仮オッズ'!$A$3,$I$4,'B馬券購入'!C5='仮オッズ'!$A$4,$I$5,'B馬券購入'!C5='仮オッズ'!$A$5,$I$6,'B馬券購入'!C5='仮オッズ'!$A$6,$I$7,'B馬券購入'!C5='仮オッズ'!$A$7,$I$8) -> 0.025 | H15: =IFS('B馬券購入'!D5='仮オッズ'!$A$2,$I$3,'B馬券購入'!D5='仮オッズ'!$A$3,$I$4,'B馬券購入'!D5='仮オッズ'!$A$4,$I$5,'B馬券購入'!D5='仮オッズ'!$A$5,$I$6,'B馬券購入'!D5='仮オッズ'!$A$6,$I$7,'B馬券購入'!D5='仮オッズ'!$A$7,$I$8) -> 0.075
A16: 三連単 | B16: =1/((F13*(G13/(1-F13))*(H13/(1-F13-G13)))) -> 2537.1429 | F16: =IFS('B馬券購入'!B6='仮オッズ'!$A$2,$I$3,'B馬券購入'!B6='仮オッズ'!$A$3,$I$4,'B馬券購入'!B6='仮オッズ'!$A$4,$I$5,'B馬券購入'!B6='仮オッズ'!$A$5,$I$6,'B馬券購入'!B6='仮オッズ'!$A$6,$I$7,'B馬券購入'!B6='仮オッズ'!$A$7,$I$8) -> 0.075 | G16: =IFS('B馬券購入'!C6='仮オッズ'!$A$2,$I$3,'B馬券購入'!C6='仮オッズ'!$A$3,$I$4,'B馬券購入'!C6='仮オッズ'!$A$4,$I$5,'B馬券購入'!C6='仮オッズ'!$A$5,$I$6,'B馬券購入'!C6='仮オッズ'!$A$6,$I$7,'B馬券購入'!C6='仮オッズ'!$A$7,$I$8) -> 0.075 | H16: =IFS('B馬券購入'!D6='仮オッズ'!$A$2,$I$3,'B馬券購入'!D6='仮オッズ'!$A$3,$I$4,'B馬券購入'!D6='仮オッズ'!$A$4,$I$5,'B馬券購入'!D6='仮オッズ'!$A$5,$I$6,'B馬券購入'!D6='仮オッズ'!$A$6,$I$7,'B馬券購入'!D6='仮オッズ'!$A$7,$I$8) -> 0.175
A17: 三連複 | B17: =1/(F13*(G13/(1-F13))*(H13/(1-F13-G13))+F13*(H13/(1-F13))*(G13/(1-F13-H13))+G13*(F13/(1-G13))*(H13/(1-F13-G13))+G13*(H13/(1-G13))*(F13/(1-G13-H13))+H13*(F13/(1-H13))*(G13/(1-H13-F13))+H13*(G13/(1-H13))*(F13/(1-G13-F13))) -> 379.65879 | F17: =IFS('B馬券購入'!B7='仮オッズ'!$A$2,$I$3,'B馬券購入'!B7='仮オッズ'!$A$3,$I$4,'B馬券購入'!B7='仮オッズ'!$A$4,$I$5,'B馬券購入'!B7='仮オッズ'!$A$5,$I$6,'B馬券購入'!B7='仮オッズ'!$A$6,$I$7,'B馬券購入'!B7='仮オッズ'!$A$7,$I$8) -> #N/A | G17: =IFS('B馬券購入'!C7='仮オッズ'!$A$2,$I$3,'B馬券購入'!C7='仮オッズ'!$A$3,$I$4,'B馬券購入'!C7='仮オッズ'!$A$4,$I$5,'B馬券購入'!C7='仮オッズ'!$A$5,$I$6,'B馬券購入'!C7='仮オッズ'!$A$6,$I$7,'B馬券購入'!C7='仮オッズ'!$A$7,$I$8) -> #N/A | H17: =IFS('B馬券購入'!D7='仮オッズ'!$A$2,$I$3,'B馬券購入'!D7='仮オッズ'!$A$3,$I$4,'B馬券購入'!D7='仮オッズ'!$A$4,$I$5,'B馬券購入'!D7='仮オッズ'!$A$5,$I$6,'B馬券購入'!D7='仮オッズ'!$A$6,$I$7,'B馬券購入'!D7='仮オッズ'!$A$7,$I$8) -> #N/A
F18: =IFS('B馬券購入'!B8='仮オッズ'!$A$2,$I$3,'B馬券購入'!B8='仮オッズ'!$A$3,$I$4,'B馬券購入'!B8='仮オッズ'!$A$4,$I$5,'B馬券購入'!B8='仮オッズ'!$A$5,$I$6,'B馬券購入'!B8='仮オッズ'!$A$6,$I$7,'B馬券購入'!B8='仮オッズ'!$A$7,$I$8) -> #N/A | G18: =IFS('B馬券購入'!C8='仮オッズ'!$A$2,$I$3,'B馬券購入'!C8='仮オッズ'!$A$3,$I$4,'B馬券購入'!C8='仮オッズ'!$A$4,$I$5,'B馬券購入'!C8='仮オッズ'!$A$5,$I$6,'B馬券購入'!C8='仮オッズ'!$A$6,$I$7,'B馬券購入'!C8='仮オッズ'!$A$7,$I$8) -> #N/A | H18: =IFS('B馬券購入'!D8='仮オッズ'!$A$2,$I$3,'B馬券購入'!D8='仮オッズ'!$A$3,$I$4,'B馬券購入'!D8='仮オッズ'!$A$4,$I$5,'B馬券購入'!D8='仮オッズ'!$A$5,$I$6,'B馬券購入'!D8='仮オッズ'!$A$6,$I$7,'B馬券購入'!D8='仮オッズ'!$A$7,$I$8) -> #N/A
B19: 計算した値 | C19: 1.1の調整 | D19: 表示する値 | F19: =IFS('B馬券購入'!B9='仮オッズ'!$A$2,$I$3,'B馬券購入'!B9='仮オッズ'!$A$3,$I$4,'B馬券購入'!B9='仮オッズ'!$A$4,$I$5,'B馬券購入'!B9='仮オッズ'!$A$5,$I$6,'B馬券購入'!B9='仮オッズ'!$A$6,$I$7,'B馬券購入'!B9='仮オッズ'!$A$7,$I$8) -> #N/A | G19: =IFS('B馬券購入'!C9='仮オッズ'!$A$2,$I$3,'B馬券購入'!C9='仮オッズ'!$A$3,$I$4,'B馬券購入'!C9='仮オッズ'!$A$4,$I$5,'B馬券購入'!C9='仮オッズ'!$A$5,$I$6,'B馬券購入'!C9='仮オッズ'!$A$6,$I$7,'B馬券購入'!C9='仮オッズ'!$A$7,$I$8) -> #N/A | H19: =IFS('B馬券購入'!D9='仮オッズ'!$A$2,$I$3,'B馬券購入'!D9='仮オッズ'!$A$3,$I$4,'B馬券購入'!D9='仮オッズ'!$A$4,$I$5,'B馬券購入'!D9='仮オッズ'!$A$5,$I$6,'B馬券購入'!D9='仮オッズ'!$A$6,$I$7,'B馬券購入'!D9='仮オッズ'!$A$7,$I$8) -> #N/A
A20: 3列目 | B20: =IFS('B馬券購入'!A3="単勝",$B$14,'B馬券購入'!A3="複勝",$B$15,'B馬券購入'!A3="三連単",$B$16,'B馬券購入'!A3="三連複",$B$17) -> 379.65879 | C20: =IF(B20<1.1,1.1,B20) -> 379.65879 | D20: =IFERROR(C20,"未選択") -> 379.65879
A21: 4列目 | B21: =IFS('B馬券購入'!A4="単勝",$G$22,'B馬券購入'!A4="複勝",$G$23,'B馬券購入'!A4="三連単",$G$24,'B馬券購入'!A4="三連複",$G$25) -> 365.16982 | C21: =IF(B21<1.1,1.1,B21) -> 365.16982 | D21: =IFERROR(C21,"未選択") -> 365.16982 | F21: ４列目 | G21: オッズ | H21: 的・不的 | I21: ５列目 | K21: 的・不的 | L21: ６列目 | O21: 7列目
A22: 5列目 | B22: =IFS('B馬券購入'!A5="単勝",$J$22,'B馬券購入'!A5="複勝",$J$23,'B馬券購入'!A5="三連単",$J$24,'B馬券購入'!A5="三連複",$J$25) -> 1008.3963 | C22: =IF(B22<1.1,1.1,B22) -> 1008.3963 | D22: =IFERROR(C22,"未選択") -> 1008.3963 | F22: 単勝 | G22: =VLOOKUP('B馬券購入'!B$4,'②の計算式'!単勝,2,false) -> 5.7142857 | H22: =IF('B馬券購入'!B4='仮オッズ'!$B$17,"的中","不的中") -> 不的中 | I22: 単勝 | J22: =VLOOKUP('B馬券購入'!$B$5,'②の計算式'!単勝,2,false) -> 13.333333 | K22: =IF('B馬券購入'!B5='仮オッズ'!$B$17,"的中","不的中") -> 不的中 | L22: 単勝 | M22: =VLOOKUP('B馬券購入'!$B$6,'②の計算式'!単勝,2,false) -> 13.333333 | N22: =IF('B馬券購入'!B6='仮オッズ'!$B$17,"的中","不的中") -> 不的中 | O22: 単勝 | P22: =VLOOKUP('B馬券購入'!$B$7,'②の計算式'!単勝,2,false) -> #N/A | Q22: =IF('B馬券購入'!B7='仮オッズ'!$B$17,"的中","不的中") -> 不的中
A23: ６列目 | B23: =IFS('B馬券購入'!A6="単勝",$M$22,'B馬券購入'!A6="複勝",$M$23,'B馬券購入'!A6="三連単",$M$24,'B馬券購入'!A6="三連複",$M$25) -> 122.61349 | C23: =IF(B23<1.1,1.1,B23) -> 122.61349 | D23: =IFERROR(C23,"未選択") -> 122.61349 | F23: 複勝 | G23: =VLOOKUP('B馬券購入'!$B$4,'②の計算式'!複勝,2,false) -> 2.280583 | H23: =IF(OR('B馬券購入'!B4='仮オッズ'!$B$17,'B馬券購入'!B4='仮オッズ'!$B$18,'B馬券購入'!B4='仮オッズ'!$B$19),"的中","不的中") -> 的中 | I23: 複勝 | J23: =VLOOKUP('B馬券購入'!$B$5,'②の計算式'!複勝,2,false) -> 4.795085 | K23: =IF(OR('B馬券購入'!B5='仮オッズ'!$B$17,'B馬券購入'!B5='仮オッズ'!$B$18,'B馬券購入'!B5='仮オッズ'!$B$19),"的中","不的中") -> 的中 | L23: 複勝 | M23: =VLOOKUP('B馬券購入'!$B$6,'②の計算式'!複勝,2,false) -> 4.795085 | N23: =IF(OR('B馬券購入'!B6='仮オッズ'!$B$17,'B馬券購入'!B6='仮オッズ'!$B$18,'B馬券購入'!B6='仮オッズ'!$B$19),"的中","不的中") -> 的中 | O23: 複勝 | P23: =VLOOKUP('B馬券購入'!$B$7,'②の計算式'!複勝,2,false) -> #N/A | Q23: =IF(OR('B馬券購入'!B7='仮オッズ'!$B$17,'B馬券購入'!B7='仮オッズ'!$B$18,'B馬券購入'!B7='仮オッズ'!$B$19),"的中","不的中") -> 不的中
A24: 7列目 | B24: =IFS('B馬券購入'!A7="単勝",$P$22,'B馬券購入'!A7="複勝",$P$23,'B馬券購入'!A7="三連単",$P$24,'B馬券購入'!A7="三連複",$P$25) -> #N/A | C24: =IF(B24<1.1,1.1,B24) -> #N/A | D24: =IFERROR(C24,"未選択") -> 未選択 | F24: 三連単 | G24: =1/((F14*(G14/(1-F14))*(H14/(1-F14-G14)))) -> 2011.4286 | H24: =if(AND('B馬券購入'!B4='仮オッズ'!$B$17,'B馬券購入'!C4='仮オッズ'!$B$18,'B馬券購入'!D4='仮オッズ'!$B$19),"的中","不的中") -> 不的中 | I24: 三連単 | J24: =1/((F15*(G15/(1-F15))*(H15/(1-F15-G15)))) -> 5920 | K24: =if(AND('B馬券購入'!B5='仮オッズ'!$B$17,'B馬券購入'!C5='仮オッズ'!$B$18,'B馬券購入'!D5='仮オッズ'!$B$19),"的中","不的中") -> 不的中 | L24: 三連単 | M24: =1/((F16*(G16/(1-F16))*(H16/(1-F16-G16)))) -> 798.73016 | N24: =if(AND('B馬券購入'!B6='仮オッズ'!$B$17,'B馬券購入'!C6='仮オッズ'!$B$18,'B馬券購入'!D6='仮オッズ'!$B$19),"的中","不的中") -> 不的中 | O24: 三連単 | P24: =1/((F17*(G17/(1-F17))*(H17/(1-F17-G17)))) -> #N/A | Q24: =if(AND('B馬券購入'!B7='仮オッズ'!$B$17,'B馬券購入'!C7='仮オッズ'!$B$18,'B馬券購入'!D7='仮オッズ'!$B$19),"的中","不的中") -> 不的中
F25: 三連複 | G25: =1/(F14*(G14/(1-F14))*(H14/(1-F14-G14))+F14*(H14/(1-F14))*(G14/(1-F14-H14))+G14*(F14/(1-G14))*(H14/(1-F14-G14))+G14*(H14/(1-G14))*(F14/(1-G14-H14))+H14*(F14/(1-H14))*(G14/(1-H14-F14))+H14*(G14/(1-H14))*(F14/(1-G14-F14))) -> 365.16982 | H25: =IF(AND(OR('仮オッズ'!$B$17='B馬券購入'!B4,'仮オッズ'!$B$18='B馬券購入'!B4,'仮オッズ'!$B$19='B馬券購入'!B4),OR('仮オッズ'!$B$17='B馬券購入'!C4,'仮オッズ'!$B$18='B馬券購入'!C4,'仮オッズ'!$B$19='B馬券購入'!C4),OR('仮オッズ'!$B$17='B馬券購入'!D4,'仮オッズ'!$B$18='B馬券購入'!D4,'仮オッズ'!$B$19='B馬券購入'!D4)),"的中","不的中") -> 不的中 | I25: 三連複 | J25: =1/(F15*(G15*(1-F15))*(H15/(1-F15-G15))+F15*(H15/(1-F15))*(G15/(1-F15-H15))+G15*(F15/(1-G15))*(H15/(1-F15-G15))+G15*(H15/(1-G15))*(F15/(1-G15-H15))+H15*(F15/(1-H15))*(G15/(1-H15-F15))+H15*(G15/(1-H15))*(F15/(1-G15-F15))) -> 1008.3963 | K25: =IF(AND(OR('仮オッズ'!$B$17='B馬券購入'!B5,'仮オッズ'!$B$18='B馬券購入'!B5,'仮オッズ'!$B$19='B馬券購入'!B5),OR('仮オッズ'!$B$17='B馬券購入'!C5,'仮オッズ'!$B$18='B馬券購入'!C5,'仮オッズ'!$B$19='B馬券購入'!C5),OR('仮オッズ'!$B$17='B馬券購入'!D5,'仮オッズ'!$B$18='B馬券購入'!D5,'仮オッズ'!$B$19='B馬券購入'!D5)),"的中","不的中") -> 不的中 | L25: 三連複 | M25: =1/(F16*(G16*(1-F16))*(H16/(1-F16-G16))+F16*(H16/(1-F16))*(G16/(1-F16-H16))+G16*(F16/(1-G16))*(H16/(1-F16-G16))+G16*(H16/(1-G16))*(F16/(1-G16-H16))+H16*(F16/(1-H16))*(G16/(1-H16-F16))+H16*(G16/(1-H16))*(F16/(1-G16-F16))) -> 122.61349 | N25: =IF(AND(OR('仮オッズ'!$B$17='B馬券購入'!B6,'仮オッズ'!$B$18='B馬券購入'!B6,'仮オッズ'!$B$19='B馬券購入'!B6),OR('仮オッズ'!$B$17='B馬券購入'!C6,'仮オッズ'!$B$18='B馬券購入'!C6,'仮オッズ'!$B$19='B馬券購入'!C6),OR('仮オッズ'!$B$17='B馬券購入'!D6,'仮オッズ'!$B$18='B馬券購入'!D6,'仮オッズ'!$B$19='B馬券購入'!D6)),"的中","不的中") -> 的中 | O25: 三連複 | P25: =1/(F17*(G17*(1-F17))*(H17/(1-F17-G17))+F17*(H17/(1-F17))*(G17/(1-F17-H17))+G17*(F17/(1-G17))*(H17/(1-F17-G17))+G17*(H17/(1-G17))*(F17/(1-G17-H17))+H17*(F17/(1-H17))*(G17/(1-H17-F17))+H17*(G17/(1-H17))*(F17/(1-G17-F17))) -> #N/A | Q25: =IF(AND(OR('仮オッズ'!$B$17='B馬券購入'!B7,'仮オッズ'!$B$18='B馬券購入'!B7,'仮オッズ'!$B$19='B馬券購入'!B7),OR('仮オッズ'!$B$17='B馬券購入'!C7,'仮オッズ'!$B$18='B馬券購入'!C7,'仮オッズ'!$B$19='B馬券購入'!C7),OR('仮オッズ'!$B$17='B馬券購入'!D7,'仮オッズ'!$B$18='B馬券購入'!D7,'仮オッズ'!$B$19='B馬券購入'!D7)),"的中","不的中") -> 不的中
B27: ３列目
B28: 単勝の時 | C28: =IF('B馬券購入'!B3='仮オッズ'!$B$17,"的中","不的中") -> 不的中
B29: 三連単の時 | C29: =if(AND('B馬券購入'!B3='仮オッズ'!$B$17,'B馬券購入'!C3='仮オッズ'!$B$18,'B馬券購入'!D3='仮オッズ'!$B$19),"的中","不的中") -> 不的中
B30: 複勝のとき | C30: =IF(OR('B馬券購入'!B3='仮オッズ'!$B$17,'B馬券購入'!B3='仮オッズ'!$B$18,'B馬券購入'!B3='仮オッズ'!$B$19),"的中","不的中") -> 的中
B31: 三連複のとき | C31: =IF(AND(OR('仮オッズ'!$B$17='B馬券購入'!B3,'仮オッズ'!$B$18='B馬券購入'!B3,'仮オッズ'!$B$19='B馬券購入'!B3),OR('仮オッズ'!$B$17='B馬券購入'!C3,'仮オッズ'!$B$18='B馬券購入'!C3,'仮オッズ'!$B$19='B馬券購入'!C3),OR('仮オッズ'!$B$17='B馬券購入'!D3,'仮オッズ'!$B$18='B馬券購入'!D3,'仮オッズ'!$B$19='B馬券購入'!D3)),"的中","不的中") -> 不的中
B34: 表示する値 | C34: 当選金額 | F34: 合計金額
A35: 3列目 | B35: =IFS('B馬券購入'!A3="単勝",$C$28,'B馬券購入'!A3="三連単",$C$29,'B馬券購入'!A3="複勝",$C$30,'B馬券購入'!A3="三連複",$C$31,'B馬券購入'!A3="未選択","×") -> 不的中 | C35: =IFS(B35="的中",'B馬券購入'!E3*'B馬券購入'!F3,B35="不的中",0,B35="×",0) -> 0 | F35: =CEILING(SUM(C35:C39),5) -> 36785
A36: 4列目 | B36: =IFS('B馬券購入'!A4="単勝",$H$22,'B馬券購入'!A4="三連単",$H$24,'B馬券購入'!A4="複勝",$H$23,'B馬券購入'!A4="三連複",$H$25,'B馬券購入'!A4="未選択","×") -> 不的中 | C36: =IFS(B36="的中",'B馬券購入'!E4*'B馬券購入'!F4,B36="不的中",0,B36="×",0) -> 0
A37: 5列目 | B37: =IFS('B馬券購入'!A5="単勝",$K$22,'B馬券購入'!A5="三連単",$K$24,'B馬券購入'!A5="複勝",$K$23,'B馬券購入'!A5="三連複",$K$25,'B馬券購入'!A5="未選択","×") -> 不的中 | C37: =IFS(B37="的中",'B馬券購入'!E5*'B馬券購入'!F5,B37="不的中",0,B37="×",0) -> 0
A38: ６列目 | B38: =IFS('B馬券購入'!A6="単勝",$N$22,'B馬券購入'!A6="三連単",$N$24,'B馬券購入'!A6="複勝",$N$23,'B馬券購入'!A6="三連複",$N$25,'B馬券購入'!A6="未選択","×") -> 的中 | C38: =IFS(B38="的中",'B馬券購入'!E6*'B馬券購入'!F6,B38="不的中",0,B38="×",0) -> 36784.048
A39: 7列目 | B39: =IFS('B馬券購入'!A7="単勝",$Q$22,'B馬券購入'!A7="三連単",$Q$24,'B馬券購入'!A7="複勝",$Q$23,'B馬券購入'!A7="三連複",$Q$25,'B馬券購入'!A7="未選択","×") -> × | C39: =IFS(B39="的中",'B馬券購入'!E7*'B馬券購入'!F7,B39="不的中",0,B39="×",0) -> 0

Sheet B馬券購入
A2: 券種 | B2: 賭ける人 | E2: 賭けPt | F2: オッズ | G2: 的・不的 | H2: 合計賭け金
A3: 三連複 | B3: みわ | C3: いずみ | D3: はせりょー | E3: 300 | F3: ='②の計算式'!D20 -> 379.65879 | G3: =IF(COUNTIF('仮オッズ'!$A$17:$B$22,"未選択")>0,"×",'②の計算式'!B35) -> 不的中 | H3: =SUM(E3:E7) -> 1250
A4: 三連複 | B4: はせりょー | C4: いずみ | D4: こーた | E4: 300 | F4: ='②の計算式'!D21 -> 365.16982 | G4: =IF(COUNTIF('仮オッズ'!$A$17:$B$22,"未選択")>0,"×",'②の計算式'!B36) -> 不的中 | H4: 払い戻し金
A5: 三連複 | B5: みわ | C5: いずみ | D5: こーた | E5: 300 | F5: ='②の計算式'!D22 -> 1008.3963 | G5: =IF(COUNTIF('仮オッズ'!$A$17:$B$22,"未選択")>0,"×",'②の計算式'!B37) -> 不的中 | H5: =IF(COUNTIF('仮オッズ'!$B$17:$B$22,"未選択")>0,"×",'②の計算式'!F35) -> 36785
A6: 三連複 | B6: みわ | C6: こーた | D6: はせりょー | E6: 300 | F6: ='②の計算式'!D23 -> 122.61349 | G6: =IF(COUNTIF('仮オッズ'!$A$17:$B$22,"未選択")>0,"×",'②の計算式'!B38) -> 的中 | H6: 収支
A7: 未選択 | B7: 未選択 | C7: 未選択 | D7: 未選択 | E7: 50 | F7: ='②の計算式'!D24 -> 未選択 | G7: =IF(COUNTIF('仮オッズ'!$A$17:$B$22,"未選択")>0,"×",'②の計算式'!B39) -> × | H7: =IF(H5="×","×",H5-H3) -> 35535

Sheet ③の計算式
I1: xが1着になる確率
B2: 単勝 | E2: 複勝 | H2: 三連 | I2: p(x)
B3: ='仮オッズ'!A2 -> ゆーや | C3: ='仮オッズ'!D2 -> 2.1052632 | E3: ='仮オッズ'!A2 -> ゆーや | F3: =1/(1-(1-(1/'仮オッズ'!D2))^3) -> 1.1691847 | H3: ='仮オッズ'!A2 -> ゆーや | I3: =1/C3 -> 0.475
B4: ='仮オッズ'!A3 -> たいよう | C4: ='仮オッズ'!D3 -> 2.3529412 | E4: ='仮オッズ'!A3 -> たいよう | F4: =1/(1-(1-(1/'仮オッズ'!D3))^3) -> 1.2347346 | H4: ='仮オッズ'!A3 -> たいよう | I4: =1/C4 -> 0.425
B5: ='仮オッズ'!A4 -> はせりょー | C5: ='仮オッズ'!D4 -> 5.7142857 | E5: ='仮オッズ'!A4 -> はせりょー | F5: =1/(1-(1-(1/'仮オッズ'!D4))^3) -> 2.280583 | H5: ='仮オッズ'!A4 -> はせりょー | I5: =1/C5 -> 0.175
B6: ='仮オッズ'!A5 -> みわ | C6: ='仮オッズ'!D5 -> 13.333333 | E6: ='仮オッズ'!A5 -> みわ | F6: =1/(1-(1-(1/'仮オッズ'!D5))^3) -> 4.795085 | H6: ='仮オッズ'!A5 -> みわ | I6: =1/C6 -> 0.075
B7: ='仮オッズ'!A6 -> こーた | C7: ='仮オッズ'!D6 -> 13.333333 | E7: ='仮オッズ'!A6 -> こーた | F7: =1/(1-(1-(1/'仮オッズ'!D6))^3) -> 4.795085 | H7: ='仮オッズ'!A6 -> こーた | I7: =1/C7 -> 0.075
B8: ='仮オッズ'!A7 -> いずみ | C8: ='仮オッズ'!D7 -> 40 | E8: ='仮オッズ'!A7 -> いずみ | F8: =1/(1-(1-(1/'仮オッズ'!D7))^3) -> 13.672292 | H8: ='仮オッズ'!A7 -> いずみ | I8: =1/C8 -> 0.025
B9: ='仮オッズ'!A8 -> 未選択 | C9: ='仮オッズ'!D8 | E9: ='仮オッズ'!A8 -> 未選択 | H9: ='仮オッズ'!A8 -> 未選択
B10: ='仮オッズ'!A9 | C10: ='仮オッズ'!D9:D18 | E10: ='仮オッズ'!A9 | H10: ='仮オッズ'!A9
B11: ='仮オッズ'!A10 | E11: ='仮オッズ'!A10 | H11: ='仮オッズ'!A10
B12: 3列目 | F12: 三連
F13: =IFS('C馬券購入'!B3='仮オッズ'!$A$2,$I$3,'C馬券購入'!B3='仮オッズ'!$A$3,$I$4,'C馬券購入'!B3='仮オッズ'!$A$4,$I$5,'C馬券購入'!B3='仮オッズ'!$A$5,$I$6,'C馬券購入'!B3='仮オッズ'!$A$6,$I$7,'C馬券購入'!B3='仮オッズ'!$A$7,$I$8) -> 0.175 | G13: =IFS('C馬券購入'!C3='仮オッズ'!$A$2,$I$3,'C馬券購入'!C3='仮オッズ'!$A$3,$I$4,'C馬券購入'!C3='仮オッズ'!$A$4,$I$5,'C馬券購入'!C3='仮オッズ'!$A$5,$I$6,'C馬券購入'!C3='仮オッズ'!$A$6,$I$7,'C馬券購入'!C3='仮オッズ'!$A$7,$I$8) -> #N/A | H13: =IFS('C馬券購入'!D3='仮オッズ'!$A$2,$I$3,'C馬券購入'!D3='仮オッズ'!$A$3,$I$4,'C馬券購入'!D3='仮オッズ'!$A$4,$I$5,'C馬券購入'!D3='仮オッズ'!$A$5,$I$6,'C馬券購入'!D3='仮オッズ'!$A$6,$I$7,'C馬券購入'!D3='仮オッズ'!$A$7,$I$8) -> #N/A
A14: 単勝 | B14: =VLOOKUP('C馬券購入'!B$3,'③の計算式'!単勝,2,false) -> 5.7142857 | F14: =IFS('C馬券購入'!B4='仮オッズ'!$A$2,$I$3,'C馬券購入'!B4='仮オッズ'!$A$3,$I$4,'C馬券購入'!B4='仮オッズ'!$A$4,$I$5,'C馬券購入'!B4='仮オッズ'!$A$5,$I$6,'C馬券購入'!B4='仮オッズ'!$A$6,$I$7,'C馬券購入'!B4='仮オッズ'!$A$7,$I$8) -> 0.025 | G14: =IFS('C馬券購入'!C4='仮オッズ'!$A$2,$I$3,'C馬券購入'!C4='仮オッズ'!$A$3,$I$4,'C馬券購入'!C4='仮オッズ'!$A$4,$I$5,'C馬券購入'!C4='仮オッズ'!$A$5,$I$6,'C馬券購入'!C4='仮オッズ'!$A$6,$I$7,'C馬券購入'!C4='仮オッズ'!$A$7,$I$8) -> #N/A | H14: =IFS('C馬券購入'!D4='仮オッズ'!$A$2,$I$3,'C馬券購入'!D4='仮オッズ'!$A$3,$I$4,'C馬券購入'!D4='仮オッズ'!$A$4,$I$5,'C馬券購入'!D4='仮オッズ'!$A$5,$I$6,'C馬券購入'!D4='仮オッズ'!$A$6,$I$7,'C馬券購入'!D4='仮オッズ'!$A$7,$I$8) -> #N/A
A15: 複勝 | B15: =VLOOKUP('C馬券購入'!B3,'③の計算式'!複勝,2,false) -> 2.280583 | F15: =IFS('C馬券購入'!B5='仮オッズ'!$A$2,$I$3,'C馬券購入'!B5='仮オッズ'!$A$3,$I$4,'C馬券購入'!B5='仮オッズ'!$A$4,$I$5,'C馬券購入'!B5='仮オッズ'!$A$5,$I$6,'C馬券購入'!B5='仮オッズ'!$A$6,$I$7,'C馬券購入'!B5='仮オッズ'!$A$7,$I$8) -> 0.425 | G15: =IFS('C馬券購入'!C5='仮オッズ'!$A$2,$I$3,'C馬券購入'!C5='仮オッズ'!$A$3,$I$4,'C馬券購入'!C5='仮オッズ'!$A$4,$I$5,'C馬券購入'!C5='仮オッズ'!$A$5,$I$6,'C馬券購入'!C5='仮オッズ'!$A$6,$I$7,'C馬券購入'!C5='仮オッズ'!$A$7,$I$8) -> #N/A | H15: =IFS('C馬券購入'!D5='仮オッズ'!$A$2,$I$3,'C馬券購入'!D5='仮オッズ'!$A$3,$I$4,'C馬券購入'!D5='仮オッズ'!$A$4,$I$5,'C馬券購入'!D5='仮オッズ'!$A$5,$I$6,'C馬券購入'!D5='仮オッズ'!$A$6,$I$7,'C馬券購入'!D5='仮オッズ'!$A$7,$I$8) -> #N/A
A16: 三連単 | B16: =1/((F13*(G13/(1-F13))*(H13/(1-F13-G13)))) -> #N/A | F16: =IFS('C馬券購入'!B6='仮オッズ'!$A$2,$I$3,'C馬券購入'!B6='仮オッズ'!$A$3,$I$4,'C馬券購入'!B6='仮オッズ'!$A$4,$I$5,'C馬券購入'!B6='仮オッズ'!$A$5,$I$6,'C馬券購入'!B6='仮オッズ'!$A$6,$I$7,'C馬券購入'!B6='仮オッズ'!$A$7,$I$8) -> 0.075 | G16: =IFS('C馬券購入'!C6='仮オッズ'!$A$2,$I$3,'C馬券購入'!C6='仮オッズ'!$A$3,$I$4,'C馬券購入'!C6='仮オッズ'!$A$4,$I$5,'C馬券購入'!C6='仮オッズ'!$A$5,$I$6,'C馬券購入'!C6='仮オッズ'!$A$6,$I$7,'C馬券購入'!C6='仮オッズ'!$A$7,$I$8) -> #N/A | H16: =IFS('C馬券購入'!D6='仮オッズ'!$A$2,$I$3,'C馬券購入'!D6='仮オッズ'!$A$3,$I$4,'C馬券購入'!D6='仮オッズ'!$A$4,$I$5,'C馬券購入'!D6='仮オッズ'!$A$5,$I$6,'C馬券購入'!D6='仮オッズ'!$A$6,$I$7,'C馬券購入'!D6='仮オッズ'!$A$7,$I$8) -> #N/A
A17: 三連複 | B17: =1/(F13*(G13/(1-F13))*(H13/(1-F13-G13))+F13*(H13/(1-F13))*(G13/(1-F13-H13))+G13*(F13/(1-G13))*(H13/(1-F13-G13))+G13*(H13/(1-G13))*(F13/(1-G13-H13))+H13*(F13/(1-H13))*(G13/(1-H13-F13))+H13*(G13/(1-H13))*(F13/(1-G13-F13))) -> #N/A | F17: =IFS('C馬券購入'!B7='仮オッズ'!$A$2,$I$3,'C馬券購入'!B7='仮オッズ'!$A$3,$I$4,'C馬券購入'!B7='仮オッズ'!$A$4,$I$5,'C馬券購入'!B7='仮オッズ'!$A$5,$I$6,'C馬券購入'!B7='仮オッズ'!$A$6,$I$7,'C馬券購入'!B7='仮オッズ'!$A$7,$I$8) -> 0.025 | G17: =IFS('C馬券購入'!C7='仮オッズ'!$A$2,$I$3,'C馬券購入'!C7='仮オッズ'!$A$3,$I$4,'C馬券購入'!C7='仮オッズ'!$A$4,$I$5,'C馬券購入'!C7='仮オッズ'!$A$5,$I$6,'C馬券購入'!C7='仮オッズ'!$A$6,$I$7,'C馬券購入'!C7='仮オッズ'!$A$7,$I$8) -> #N/A | H17: =IFS('C馬券購入'!D7='仮オッズ'!$A$2,$I$3,'C馬券購入'!D7='仮オッズ'!$A$3,$I$4,'C馬券購入'!D7='仮オッズ'!$A$4,$I$5,'C馬券購入'!D7='仮オッズ'!$A$5,$I$6,'C馬券購入'!D7='仮オッズ'!$A$6,$I$7,'C馬券購入'!D7='仮オッズ'!$A$7,$I$8) -> #N/A
F18: =IFS('C馬券購入'!B8='仮オッズ'!$A$2,$I$3,'C馬券購入'!B8='仮オッズ'!$A$3,$I$4,'C馬券購入'!B8='仮オッズ'!$A$4,$I$5,'C馬券購入'!B8='仮オッズ'!$A$5,$I$6,'C馬券購入'!B8='仮オッズ'!$A$6,$I$7,'C馬券購入'!B8='仮オッズ'!$A$7,$I$8) -> #N/A | G18: =IFS('C馬券購入'!C8='仮オッズ'!$A$2,$I$3,'C馬券購入'!C8='仮オッズ'!$A$3,$I$4,'C馬券購入'!C8='仮オッズ'!$A$4,$I$5,'C馬券購入'!C8='仮オッズ'!$A$5,$I$6,'C馬券購入'!C8='仮オッズ'!$A$6,$I$7,'C馬券購入'!C8='仮オッズ'!$A$7,$I$8) -> #N/A | H18: =IFS('C馬券購入'!D8='仮オッズ'!$A$2,$I$3,'C馬券購入'!D8='仮オッズ'!$A$3,$I$4,'C馬券購入'!D8='仮オッズ'!$A$4,$I$5,'C馬券購入'!D8='仮オッズ'!$A$5,$I$6,'C馬券購入'!D8='仮オッズ'!$A$6,$I$7,'C馬券購入'!D8='仮オッズ'!$A$7,$I$8) -> #N/A
B19: 計算した値 | C19: 1.1の調整 | D19: 表示する値 | F19: =IFS('C馬券購入'!B9='仮オッズ'!$A$2,$I$3,'C馬券購入'!B9='仮オッズ'!$A$3,$I$4,'C馬券購入'!B9='仮オッズ'!$A$4,$I$5,'C馬券購入'!B9='仮オッズ'!$A$5,$I$6,'C馬券購入'!B9='仮オッズ'!$A$6,$I$7,'C馬券購入'!B9='仮オッズ'!$A$7,$I$8) -> #N/A | G19: =IFS('C馬券購入'!C9='仮オッズ'!$A$2,$I$3,'C馬券購入'!C9='仮オッズ'!$A$3,$I$4,'C馬券購入'!C9='仮オッズ'!$A$4,$I$5,'C馬券購入'!C9='仮オッズ'!$A$5,$I$6,'C馬券購入'!C9='仮オッズ'!$A$6,$I$7,'C馬券購入'!C9='仮オッズ'!$A$7,$I$8) -> #N/A | H19: =IFS('C馬券購入'!D9='仮オッズ'!$A$2,$I$3,'C馬券購入'!D9='仮オッズ'!$A$3,$I$4,'C馬券購入'!D9='仮オッズ'!$A$4,$I$5,'C馬券購入'!D9='仮オッズ'!$A$5,$I$6,'C馬券購入'!D9='仮オッズ'!$A$6,$I$7,'C馬券購入'!D9='仮オッズ'!$A$7,$I$8) -> #N/A
A20: 3列目 | B20: =IFS('C馬券購入'!A3="単勝",$B$14,'C馬券購入'!A3="複勝",$B$15,'C馬券購入'!A3="三連単",$B$16,'C馬券購入'!A3="三連複",$B$17) -> 2.280583 | C20: =IF(B20<1.1,1.1,B20) -> 2.280583 | D20: =IFERROR(C20,"未選択") -> 2.280583
A21: 4列目 | B21: =IFS('C馬券購入'!A4="単勝",$G$22,'C馬券購入'!A4="複勝",$G$23,'C馬券購入'!A4="三連単",$G$24,'C馬券購入'!A4="三連複",$G$25) -> 13.672292 | C21: =IF(B21<1.1,1.1,B21) -> 13.672292 | D21: =IFERROR(C21,"未選択") -> 13.672292 | F21: ４列目 | G21: オッズ | H21: 的・不的 | I21: ５列目 | K21: 的・不的 | L21: ６列目 | O21: 7列目
A22: 5列目 | B22: =IFS('C馬券購入'!A5="単勝",$J$22,'C馬券購入'!A5="複勝",$J$23,'C馬券購入'!A5="三連単",$J$24,'C馬券購入'!A5="三連複",$J$25) -> 2.3529412 | C22: =IF(B22<1.1,1.1,B22) -> 2.3529412 | D22: =IFERROR(C22,"未選択") -> 2.3529412 | F22: 単勝 | G22: =VLOOKUP('C馬券購入'!B$4,'③の計算式'!単勝,2,false) -> 40 | H22: =IF('C馬券購入'!B4='仮オッズ'!$B$17,"的中","不的中") -> 不的中 | I22: 単勝 | J22: =VLOOKUP('C馬券購入'!$B$5,'③の計算式'!単勝,2,false) -> 2.3529412 | K22: =IF('C馬券購入'!B5='仮オッズ'!$B$17,"的中","不的中") -> 不的中 | L22: 単勝 | M22: =VLOOKUP('C馬券購入'!$B$6,'③の計算式'!単勝,2,false) -> 13.333333 | N22: =IF('C馬券購入'!B6='仮オッズ'!$B$17,"的中","不的中") -> 不的中 | O22: 単勝 | P22: =VLOOKUP('C馬券購入'!$B$7,'③の計算式'!単勝,2,false) -> 40 | Q22: =IF('C馬券購入'!B7='仮オッズ'!$B$17,"的中","不的中") -> 不的中
A23: ６列目 | B23: =IFS('C馬券購入'!A6="単勝",$M$22,'C馬券購入'!A6="複勝",$M$23,'C馬券購入'!A6="三連単",$M$24,'C馬券購入'!A6="三連複",$M$25) -> 13.333333 | C23: =IF(B23<1.1,1.1,B23) -> 13.333333 | D23: =IFERROR(C23,"未選択") -> 13.333333 | F23: 複勝 | G23: =VLOOKUP('C馬券購入'!$B$4,'③の計算式'!複勝,2,false) -> 13.672292 | H23: =IF(OR('C馬券購入'!B4='仮オッズ'!$B$17,'C馬券購入'!B4='仮オッズ'!$B$18,'C馬券購入'!B4='仮オッズ'!$B$19),"的中","不的中") -> 不的中 | I23: 複勝 | J23: =VLOOKUP('C馬券購入'!$B$5,'③の計算式'!複勝,2,false) -> 1.2347346 | K23: =IF(OR('C馬券購入'!B5='仮オッズ'!$B$17,'C馬券購入'!B5='仮オッズ'!$B$18,'C馬券購入'!B5='仮オッズ'!$B$19),"的中","不的中") -> 不的中 | L23: 複勝 | M23: =VLOOKUP('C馬券購入'!$B$6,'③の計算式'!複勝,2,false) -> 4.795085 | N23: =IF(OR('C馬券購入'!B6='仮オッズ'!$B$17,'C馬券購入'!B6='仮オッズ'!$B$18,'C馬券購入'!B6='仮オッズ'!$B$19),"的中","不的中") -> 的中 | O23: 複勝 | P23: =VLOOKUP('C馬券購入'!$B$7,'③の計算式'!複勝,2,false) -> 13.672292 | Q23: =IF(OR('C馬券購入'!B7='仮オッズ'!$B$17,'C馬券購入'!B7='仮オッズ'!$B$18,'C馬券購入'!B7='仮オッズ'!$B$19),"的中","不的中") -> 不的中
A24: 7列目 | B24: =IFS('C馬券購入'!A7="単勝",$P$22,'C馬券購入'!A7="複勝",$P$23,'C馬券購入'!A7="三連単",$P$24,'C馬券購入'!A7="三連複",$P$25) -> 40 | C24: =IF(B24<1.1,1.1,B24) -> 40 | D24: =IFERROR(C24,"未選択") -> 40 | F24: 三連単 | G24: =1/((F14*(G14/(1-F14))*(H14/(1-F14-G14)))) -> #N/A | H24: =if(AND('C馬券購入'!B4='仮オッズ'!$B$17,'C馬券購入'!C4='仮オッズ'!$B$18,'C馬券購入'!D4='仮オッズ'!$B$19),"的中","不的中") -> 不的中 | I24: 三連単 | J24: =1/((F15*(G15/(1-F15))*(H15/(1-F15-G15)))) -> #N/A | K24: =if(AND('C馬券購入'!B5='仮オッズ'!$B$17,'C馬券購入'!C5='仮オッズ'!$B$18,'C馬券購入'!D5='仮オッズ'!$B$19),"的中","不的中") -> 不的中 | L24: 三連単 | M24: =1/((F16*(G16/(1-F16))*(H16/(1-F16-G16)))) -> #N/A | N24: =if(AND('C馬券購入'!B6='仮オッズ'!$B$17,'C馬券購入'!C6='仮オッズ'!$B$18,'C馬券購入'!D6='仮オッズ'!$B$19),"的中","不的中") -> 不的中 | O24: 三連単 | P24: =1/((F17*(G17/(1-F17))*(H17/(1-F17-G17)))) -> #N/A | Q24: =if(AND('C馬券購入'!B7='仮オッズ'!$B$17,'C馬券購入'!C7='仮オッズ'!$B$18,'C馬券購入'!D7='仮オッズ'!$B$19),"的中","不的中") -> 不的中
F25: 三連複 | G25: =1/(F14*(G14/(1-F14))*(H14/(1-F14-G14))+F14*(H14/(1-F14))*(G14/(1-F14-H14))+G14*(F14/(1-G14))*(H14/(1-F14-G14))+G14*(H14/(1-G14))*(F14/(1-G14-H14))+H14*(F14/(1-H14))*(G14/(1-H14-F14))+H14*(G14/(1-H14))*(F14/(1-G14-F14))) -> #N/A | H25: =IF(AND(OR('仮オッズ'!$B$17='C馬券購入'!B4,'仮オッズ'!$B$18='C馬券購入'!B4,'仮オッズ'!$B$19='C馬券購入'!B4),OR('仮オッズ'!$B$17='C馬券購入'!C4,'仮オッズ'!$B$18='C馬券購入'!C4,'仮オッズ'!$B$19='C馬券購入'!C4),OR('仮オッズ'!$B$17='C馬券購入'!D4,'仮オッズ'!$B$18='C馬券購入'!D4,'仮オッズ'!$B$19='C馬券購入'!D4)),"的中","不的中") -> 不的中 | I25: 三連複 | J25: =1/(F15*(G15*(1-F15))*(H15/(1-F15-G15))+F15*(H15/(1-F15))*(G15/(1-F15-H15))+G15*(F15/(1-G15))*(H15/(1-F15-G15))+G15*(H15/(1-G15))*(F15/(1-G15-H15))+H15*(F15/(1-H15))*(G15/(1-H15-F15))+H15*(G15/(1-H15))*(F15/(1-G15-F15))) -> #N/A | K25: =IF(AND(OR('仮オッズ'!$B$17='C馬券購入'!B5,'仮オッズ'!$B$18='C馬券購入'!B5,'仮オッズ'!$B$19='C馬券購入'!B5),OR('仮オッズ'!$B$17='C馬券購入'!C5,'仮オッズ'!$B$18='C馬券購入'!C5,'仮オッズ'!$B$19='C馬券購入'!C5),OR('仮オッズ'!$B$17='C馬券購入'!D5,'仮オッズ'!$B$18='C馬券購入'!D5,'仮オッズ'!$B$19='C馬券購入'!D5)),"的中","不的中") -> 不的中 | L25: 三連複 | M25: =1/(F16*(G16*(1-F16))*(H16/(1-F16-G16))+F16*(H16/(1-F16))*(G16/(1-F16-H16))+G16*(F16/(1-G16))*(H16/(1-F16-G16))+G16*(H16/(1-G16))*(F16/(1-G16-H16))+H16*(F16/(1-H16))*(G16/(1-H16-F16))+H16*(G16/(1-H16))*(F16/(1-G16-F16))) -> #N/A | N25: =IF(AND(OR('仮オッズ'!$B$17='C馬券購入'!B6,'仮オッズ'!$B$18='C馬券購入'!B6,'仮オッズ'!$B$19='C馬券購入'!B6),OR('仮オッズ'!$B$17='C馬券購入'!C6,'仮オッズ'!$B$18='C馬券購入'!C6,'仮オッズ'!$B$19='C馬券購入'!C6),OR('仮オッズ'!$B$17='C馬券購入'!D6,'仮オッズ'!$B$18='C馬券購入'!D6,'仮オッズ'!$B$19='C馬券購入'!D6)),"的中","不的中") -> 不的中 | O25: 三連複 | P25: =1/(F17*(G17*(1-F17))*(H17/(1-F17-G17))+F17*(H17/(1-F17))*(G17/(1-F17-H17))+G17*(F17/(1-G17))*(H17/(1-F17-G17))+G17*(H17/(1-G17))*(F17/(1-G17-H17))+H17*(F17/(1-H17))*(G17/(1-H17-F17))+H17*(G17/(1-H17))*(F17/(1-G17-F17))) -> #N/A | Q25: =IF(AND(OR('仮オッズ'!$B$17='C馬券購入'!B7,'仮オッズ'!$B$18='C馬券購入'!B7,'仮オッズ'!$B$19='C馬券購入'!B7),OR('仮オッズ'!$B$17='C馬券購入'!C7,'仮オッズ'!$B$18='C馬券購入'!C7,'仮オッズ'!$B$19='C馬券購入'!C7),OR('仮オッズ'!$B$17='C馬券購入'!D7,'仮オッズ'!$B$18='C馬券購入'!D7,'仮オッズ'!$B$19='C馬券購入'!D7)),"的中","不的中") -> 不的中
B27: ３列目
B28: 単勝の時 | C28: =IF('C馬券購入'!B3='仮オッズ'!$B$17,"的中","不的中") -> 不的中
B29: 三連単の時 | C29: =if(AND('C馬券購入'!B3='仮オッズ'!$B$17,'C馬券購入'!C3='仮オッズ'!$B$18,'C馬券購入'!D3='仮オッズ'!$B$19),"的中","不的中") -> 不的中
B30: 複勝のとき | C30: =IF(OR('C馬券購入'!B3='仮オッズ'!$B$17,'C馬券購入'!B3='仮オッズ'!$B$18,'C馬券購入'!B3='仮オッズ'!$B$19),"的中","不的中") -> 的中
B31: 三連複のとき | C31: =IF(AND(OR('仮オッズ'!$B$17='C馬券購入'!B3,'仮オッズ'!$B$18='C馬券購入'!B3,'仮オッズ'!$B$19='C馬券購入'!B3),OR('仮オッズ'!$B$17='C馬券購入'!C3,'仮オッズ'!$B$18='C馬券購入'!C3,'仮オッズ'!$B$19='C馬券購入'!C3),OR('仮オッズ'!$B$17='C馬券購入'!D3,'仮オッズ'!$B$18='C馬券購入'!D3,'仮オッズ'!$B$19='C馬券購入'!D3)),"的中","不的中") -> 不的中
B34: 表示する値 | C34: 当選金額 | F34: 合計金額
A35: 3列目 | B35: =IFS('C馬券購入'!A3="単勝",$C$28,'C馬券購入'!A3="三連単",$C$29,'C馬券購入'!A3="複勝",$C$30,'C馬券購入'!A3="三連複",$C$31,'C馬券購入'!A3="未選択","×") -> 的中 | C35: =IFS(B35="的中",'C馬券購入'!E3*'C馬券購入'!F3,B35="不的中",0,B35="×",0) -> 228.0583 | F35: =CEILING(SUM(C35:C39),5) -> 230
A36: 4列目 | B36: =IFS('C馬券購入'!A4="単勝",$H$22,'C馬券購入'!A4="三連単",$H$24,'C馬券購入'!A4="複勝",$H$23,'C馬券購入'!A4="三連複",$H$25,'C馬券購入'!A4="未選択","×") -> 不的中 | C36: =IFS(B36="的中",'C馬券購入'!E4*'C馬券購入'!F4,B36="不的中",0,B36="×",0) -> 0
A37: 5列目 | B37: =IFS('C馬券購入'!A5="単勝",$K$22,'C馬券購入'!A5="三連単",$K$24,'C馬券購入'!A5="複勝",$K$23,'C馬券購入'!A5="三連複",$K$25,'C馬券購入'!A5="未選択","×") -> 不的中 | C37: =IFS(B37="的中",'C馬券購入'!E5*'C馬券購入'!F5,B37="不的中",0,B37="×",0) -> 0
A38: ６列目 | B38: =IFS('C馬券購入'!A6="単勝",$N$22,'C馬券購入'!A6="三連単",$N$24,'C馬券購入'!A6="複勝",$N$23,'C馬券購入'!A6="三連複",$N$25,'C馬券購入'!A6="未選択","×") -> 不的中 | C38: =IFS(B38="的中",'C馬券購入'!E6*'C馬券購入'!F6,B38="不的中",0,B38="×",0) -> 0
A39: 7列目 | B39: =IFS('C馬券購入'!A7="単勝",$Q$22,'C馬券購入'!A7="三連単",$Q$24,'C馬券購入'!A7="複勝",$Q$23,'C馬券購入'!A7="三連複",$Q$25,'C馬券購入'!A7="未選択","×") -> 不的中 | C39: =IFS(B39="的中",'C馬券購入'!E7*'C馬券購入'!F7,B39="不的中",0,B39="×",0) -> 0

Sheet C馬券購入
A2: 券種 | B2: 賭ける人 | E2: 賭けPt | F2: オッズ | G2: 的・不的 | H2: 合計賭け金
A3: 複勝 | B3: はせりょー | C3: 未選択 | D3: 未選択 | E3: 100 | F3: ='③の計算式'!D20 -> 2.280583 | G3: =IF(COUNTIF('仮オッズ'!$A$17:$B$22,"未選択")>0,"×",'③の計算式'!B35) -> 的中 | H3: =SUM(E3:E7) -> 1050
A4: 複勝 | B4: いずみ | C4: 未選択 | D4: 未選択 | E4: 750 | F4: ='③の計算式'!D21 -> 13.672292 | G4: =IF(COUNTIF('仮オッズ'!$A$17:$B$22,"未選択")>0,"×",'③の計算式'!B36) -> 不的中 | H4: 払い戻し金
A5: 単勝 | B5: たいよう | C5: 未選択 | D5: 未選択 | E5: 50 | F5: ='③の計算式'!D22 -> 2.3529412 | G5: =IF(COUNTIF('仮オッズ'!$A$17:$B$22,"未選択")>0,"×",'③の計算式'!B37) -> 不的中 | H5: =IF(COUNTIF('仮オッズ'!$B$17:$B$22,"未選択")>0,"×",'③の計算式'!F35) -> 230
A6: 単勝 | B6: みわ | C6: 未選択 | D6: 未選択 | E6: 50 | F6: ='③の計算式'!D23 -> 13.333333 | G6: =IF(COUNTIF('仮オッズ'!$A$17:$B$22,"未選択")>0,"×",'③の計算式'!B38) -> 不的中 | H6: 収支
A7: 単勝 | B7: いずみ | C7: きょうか | D7: あんじゅ | E7: 100 | F7: ='③の計算式'!D24 -> 40 | G7: =IF(COUNTIF('仮オッズ'!$A$17:$B$22,"未選択")>0,"×",'③の計算式'!B39) -> 不的中 | H7: =IF(H5="×","×",H5-H3) -> -820

Sheet ④の計算式
I1: xが1着になる確率
B2: 単勝 | E2: 複勝 | H2: 三連 | I2: p(x)
B3: ='仮オッズ'!A2 -> ゆーや | C3: ='仮オッズ'!D2 -> 2.1052632 | E3: ='仮オッズ'!A2 -> ゆーや | F3: =1/(1-(1-(1/'仮オッズ'!D2))^3) -> 1.1691847 | H3: ='仮オッズ'!A2 -> ゆーや | I3: =1/C3 -> 0.475
B4: ='仮オッズ'!A3 -> たいよう | C4: ='仮オッズ'!D3 -> 2.3529412 | E4: ='仮オッズ'!A3 -> たいよう | F4: =1/(1-(1-(1/'仮オッズ'!D3))^3) -> 1.2347346 | H4: ='仮オッズ'!A3 -> たいよう | I4: =1/C4 -> 0.425
B5: ='仮オッズ'!A4 -> はせりょー | C5: ='仮オッズ'!D4 -> 5.7142857 | E5: ='仮オッズ'!A4 -> はせりょー | F5: =1/(1-(1-(1/'仮オッズ'!D4))^3) -> 2.280583 | H5: ='仮オッズ'!A4 -> はせりょー | I5: =1/C5 -> 0.175
B6: ='仮オッズ'!A5 -> みわ | C6: ='仮オッズ'!D5 -> 13.333333 | E6: ='仮オッズ'!A5 -> みわ | F6: =1/(1-(1-(1/'仮オッズ'!D5))^3) -> 4.795085 | H6: ='仮オッズ'!A5 -> みわ | I6: =1/C6 -> 0.075
B7: ='仮オッズ'!A6 -> こーた | C7: ='仮オッズ'!D6 -> 13.333333 | E7: ='仮オッズ'!A6 -> こーた | F7: =1/(1-(1-(1/'仮オッズ'!D6))^3) -> 4.795085 | H7: ='仮オッズ'!A6 -> こーた | I7: =1/C7 -> 0.075
B8: ='仮オッズ'!A7 -> いずみ | C8: ='仮オッズ'!D7 -> 40 | E8: ='仮オッズ'!A7 -> いずみ | F8: =1/(1-(1-(1/'仮オッズ'!D7))^3) -> 13.672292 | H8: ='仮オッズ'!A7 -> いずみ | I8: =1/C8 -> 0.025
B9: ='仮オッズ'!A8 -> 未選択 | C9: ='仮オッズ'!D8 | E9: ='仮オッズ'!A8 -> 未選択 | H9: ='仮オッズ'!A8 -> 未選択
B10: ='仮オッズ'!A9 | C10: ='仮オッズ'!D9:D18 | E10: ='仮オッズ'!A9 | H10: ='仮オッズ'!A9
B11: ='仮オッズ'!A10 | E11: ='仮オッズ'!A10 | H11: ='仮オッズ'!A10
B12: 3列目 | F12: 三連
F13: =IFS('D馬券購入'!B3='仮オッズ'!$A$2,$I$3,'D馬券購入'!B3='仮オッズ'!$A$3,$I$4,'D馬券購入'!B3='仮オッズ'!$A$4,$I$5,'D馬券購入'!B3='仮オッズ'!$A$5,$I$6,'D馬券購入'!B3='仮オッズ'!$A$6,$I$7,'D馬券購入'!B3='仮オッズ'!$A$7,$I$8) -> 0.025 | G13: =IFS('D馬券購入'!C3='仮オッズ'!$A$2,$I$3,'D馬券購入'!C3='仮オッズ'!$A$3,$I$4,'D馬券購入'!C3='仮オッズ'!$A$4,$I$5,'D馬券購入'!C3='仮オッズ'!$A$5,$I$6,'D馬券購入'!C3='仮オッズ'!$A$6,$I$7,'D馬券購入'!C3='仮オッズ'!$A$7,$I$8) -> #N/A | H13: =IFS('D馬券購入'!D3='仮オッズ'!$A$2,$I$3,'D馬券購入'!D3='仮オッズ'!$A$3,$I$4,'D馬券購入'!D3='仮オッズ'!$A$4,$I$5,'D馬券購入'!D3='仮オッズ'!$A$5,$I$6,'D馬券購入'!D3='仮オッズ'!$A$6,$I$7,'D馬券購入'!D3='仮オッズ'!$A$7,$I$8) -> #N/A
A14: 単勝 | B14: =VLOOKUP('D馬券購入'!B$3,'④の計算式'!単勝,2,false) -> 40 | F14: =IFS('D馬券購入'!B4='仮オッズ'!$A$2,$I$3,'D馬券購入'!B4='仮オッズ'!$A$3,$I$4,'D馬券購入'!B4='仮オッズ'!$A$4,$I$5,'D馬券購入'!B4='仮オッズ'!$A$5,$I$6,'D馬券購入'!B4='仮オッズ'!$A$6,$I$7,'D馬券購入'!B4='仮オッズ'!$A$7,$I$8) -> #N/A | G14: =IFS('D馬券購入'!C4='仮オッズ'!$A$2,$I$3,'D馬券購入'!C4='仮オッズ'!$A$3,$I$4,'D馬券購入'!C4='仮オッズ'!$A$4,$I$5,'D馬券購入'!C4='仮オッズ'!$A$5,$I$6,'D馬券購入'!C4='仮オッズ'!$A$6,$I$7,'D馬券購入'!C4='仮オッズ'!$A$7,$I$8) -> #N/A | H14: =IFS('D馬券購入'!D4='仮オッズ'!$A$2,$I$3,'D馬券購入'!D4='仮オッズ'!$A$3,$I$4,'D馬券購入'!D4='仮オッズ'!$A$4,$I$5,'D馬券購入'!D4='仮オッズ'!$A$5,$I$6,'D馬券購入'!D4='仮オッズ'!$A$6,$I$7,'D馬券購入'!D4='仮オッズ'!$A$7,$I$8) -> #N/A
A15: 複勝 | B15: =VLOOKUP('D馬券購入'!B3,'④の計算式'!複勝,2,false) -> 13.672292 | F15: =IFS('D馬券購入'!B5='仮オッズ'!$A$2,$I$3,'D馬券購入'!B5='仮オッズ'!$A$3,$I$4,'D馬券購入'!B5='仮オッズ'!$A$4,$I$5,'D馬券購入'!B5='仮オッズ'!$A$5,$I$6,'D馬券購入'!B5='仮オッズ'!$A$6,$I$7,'D馬券購入'!B5='仮オッズ'!$A$7,$I$8) -> #N/A | G15: =IFS('D馬券購入'!C5='仮オッズ'!$A$2,$I$3,'D馬券購入'!C5='仮オッズ'!$A$3,$I$4,'D馬券購入'!C5='仮オッズ'!$A$4,$I$5,'D馬券購入'!C5='仮オッズ'!$A$5,$I$6,'D馬券購入'!C5='仮オッズ'!$A$6,$I$7,'D馬券購入'!C5='仮オッズ'!$A$7,$I$8) -> #N/A | H15: =IFS('D馬券購入'!D5='仮オッズ'!$A$2,$I$3,'D馬券購入'!D5='仮オッズ'!$A$3,$I$4,'D馬券購入'!D5='仮オッズ'!$A$4,$I$5,'D馬券購入'!D5='仮オッズ'!$A$5,$I$6,'D馬券購入'!D5='仮オッズ'!$A$6,$I$7,'D馬券購入'!D5='仮オッズ'!$A$7,$I$8) -> #N/A
A16: 三連単 | B16: =1/((F13*(G13/(1-F13))*(H13/(1-F13-G13)))) -> #N/A | F16: =IFS('D馬券購入'!B6='仮オッズ'!$A$2,$I$3,'D馬券購入'!B6='仮オッズ'!$A$3,$I$4,'D馬券購入'!B6='仮オッズ'!$A$4,$I$5,'D馬券購入'!B6='仮オッズ'!$A$5,$I$6,'D馬券購入'!B6='仮オッズ'!$A$6,$I$7,'D馬券購入'!B6='仮オッズ'!$A$7,$I$8) -> #N/A | G16: =IFS('D馬券購入'!C6='仮オッズ'!$A$2,$I$3,'D馬券購入'!C6='仮オッズ'!$A$3,$I$4,'D馬券購入'!C6='仮オッズ'!$A$4,$I$5,'D馬券購入'!C6='仮オッズ'!$A$5,$I$6,'D馬券購入'!C6='仮オッズ'!$A$6,$I$7,'D馬券購入'!C6='仮オッズ'!$A$7,$I$8) -> #N/A | H16: =IFS('D馬券購入'!D6='仮オッズ'!$A$2,$I$3,'D馬券購入'!D6='仮オッズ'!$A$3,$I$4,'D馬券購入'!D6='仮オッズ'!$A$4,$I$5,'D馬券購入'!D6='仮オッズ'!$A$5,$I$6,'D馬券購入'!D6='仮オッズ'!$A$6,$I$7,'D馬券購入'!D6='仮オッズ'!$A$7,$I$8) -> #N/A
A17: 三連複 | B17: =1/(F13*(G13/(1-F13))*(H13/(1-F13-G13))+F13*(H13/(1-F13))*(G13/(1-F13-H13))+G13*(F13/(1-G13))*(H13/(1-F13-G13))+G13*(H13/(1-G13))*(F13/(1-G13-H13))+H13*(F13/(1-H13))*(G13/(1-H13-F13))+H13*(G13/(1-H13))*(F13/(1-G13-F13))) -> #N/A | F17: =IFS('D馬券購入'!B7='仮オッズ'!$A$2,$I$3,'D馬券購入'!B7='仮オッズ'!$A$3,$I$4,'D馬券購入'!B7='仮オッズ'!$A$4,$I$5,'D馬券購入'!B7='仮オッズ'!$A$5,$I$6,'D馬券購入'!B7='仮オッズ'!$A$6,$I$7,'D馬券購入'!B7='仮オッズ'!$A$7,$I$8) -> #N/A | G17: =IFS('D馬券購入'!C7='仮オッズ'!$A$2,$I$3,'D馬券購入'!C7='仮オッズ'!$A$3,$I$4,'D馬券購入'!C7='仮オッズ'!$A$4,$I$5,'D馬券購入'!C7='仮オッズ'!$A$5,$I$6,'D馬券購入'!C7='仮オッズ'!$A$6,$I$7,'D馬券購入'!C7='仮オッズ'!$A$7,$I$8) -> #N/A | H17: =IFS('D馬券購入'!D7='仮オッズ'!$A$2,$I$3,'D馬券購入'!D7='仮オッズ'!$A$3,$I$4,'D馬券購入'!D7='仮オッズ'!$A$4,$I$5,'D馬券購入'!D7='仮オッズ'!$A$5,$I$6,'D馬券購入'!D7='仮オッズ'!$A$6,$I$7,'D馬券購入'!D7='仮オッズ'!$A$7,$I$8) -> #N/A
F18: =IFS('D馬券購入'!B8='仮オッズ'!$A$2,$I$3,'D馬券購入'!B8='仮オッズ'!$A$3,$I$4,'D馬券購入'!B8='仮オッズ'!$A$4,$I$5,'D馬券購入'!B8='仮オッズ'!$A$5,$I$6,'D馬券購入'!B8='仮オッズ'!$A$6,$I$7,'D馬券購入'!B8='仮オッズ'!$A$7,$I$8) -> #N/A | G18: =IFS('D馬券購入'!C8='仮オッズ'!$A$2,$I$3,'D馬券購入'!C8='仮オッズ'!$A$3,$I$4,'D馬券購入'!C8='仮オッズ'!$A$4,$I$5,'D馬券購入'!C8='仮オッズ'!$A$5,$I$6,'D馬券購入'!C8='仮オッズ'!$A$6,$I$7,'D馬券購入'!C8='仮オッズ'!$A$7,$I$8) -> #N/A | H18: =IFS('D馬券購入'!D8='仮オッズ'!$A$2,$I$3,'D馬券購入'!D8='仮オッズ'!$A$3,$I$4,'D馬券購入'!D8='仮オッズ'!$A$4,$I$5,'D馬券購入'!D8='仮オッズ'!$A$5,$I$6,'D馬券購入'!D8='仮オッズ'!$A$6,$I$7,'D馬券購入'!D8='仮オッズ'!$A$7,$I$8) -> #N/A
B19: 計算した値 | C19: 1.1の調整 | D19: 表示する値 | F19: =IFS('D馬券購入'!B9='仮オッズ'!$A$2,$I$3,'D馬券購入'!B9='仮オッズ'!$A$3,$I$4,'D馬券購入'!B9='仮オッズ'!$A$4,$I$5,'D馬券購入'!B9='仮オッズ'!$A$5,$I$6,'D馬券購入'!B9='仮オッズ'!$A$6,$I$7,'D馬券購入'!B9='仮オッズ'!$A$7,$I$8) -> #N/A | G19: =IFS('D馬券購入'!C9='仮オッズ'!$A$2,$I$3,'D馬券購入'!C9='仮オッズ'!$A$3,$I$4,'D馬券購入'!C9='仮オッズ'!$A$4,$I$5,'D馬券購入'!C9='仮オッズ'!$A$5,$I$6,'D馬券購入'!C9='仮オッズ'!$A$6,$I$7,'D馬券購入'!C9='仮オッズ'!$A$7,$I$8) -> #N/A | H19: =IFS('D馬券購入'!D9='仮オッズ'!$A$2,$I$3,'D馬券購入'!D9='仮オッズ'!$A$3,$I$4,'D馬券購入'!D9='仮オッズ'!$A$4,$I$5,'D馬券購入'!D9='仮オッズ'!$A$5,$I$6,'D馬券購入'!D9='仮オッズ'!$A$6,$I$7,'D馬券購入'!D9='仮オッズ'!$A$7,$I$8) -> #N/A
A20: 3列目 | B20: =IFS('D馬券購入'!A3="単勝",$B$14,'D馬券購入'!A3="複勝",$B$15,'D馬券購入'!A3="三連単",$B$16,'D馬券購入'!A3="三連複",$B$17) -> 13.672292 | C20: =IF(B20<1.1,1.1,B20) -> 13.672292 | D20: =IFERROR(C20,"未選択") -> 13.672292
A21: 4列目 | B21: =IFS('D馬券購入'!A4="単勝",$G$22,'D馬券購入'!A4="複勝",$G$23,'D馬券購入'!A4="三連単",$G$24,'D馬券購入'!A4="三連複",$G$25) -> #N/A | C21: =IF(B21<1.1,1.1,B21) -> #N/A | D21: =IFERROR(C21,"未選択") -> 未選択 | F21: ４列目 | G21: オッズ | H21: 的・不的 | I21: ５列目 | K21: 的・不的 | L21: ６列目 | O21: 7列目
A22: 5列目 | B22: =IFS('D馬券購入'!A5="単勝",$J$22,'D馬券購入'!A5="複勝",$J$23,'D馬券購入'!A5="三連単",$J$24,'D馬券購入'!A5="三連複",$J$25) -> #N/A | C22: =IF(B22<1.1,1.1,B22) -> #N/A | D22: =IFERROR(C22,"未選択") -> 未選択 | F22: 単勝 | G22: =VLOOKUP('D馬券購入'!B$4,'④の計算式'!単勝,2,false) -> #N/A | H22: =IF('D馬券購入'!B4='仮オッズ'!$B$17,"的中","不的中") -> 不的中 | I22: 単勝 | J22: =VLOOKUP('D馬券購入'!$B$5,'④の計算式'!単勝,2,false) -> #N/A | K22: =IF('D馬券購入'!B5='仮オッズ'!$B$17,"的中","不的中") -> 不的中 | L22: 単勝 | M22: =VLOOKUP('D馬券購入'!$B$6,'④の計算式'!単勝,2,false) -> #N/A | N22: =IF('D馬券購入'!B6='仮オッズ'!$B$17,"的中","不的中") -> 不的中 | O22: 単勝 | P22: =VLOOKUP('D馬券購入'!$B$7,'④の計算式'!単勝,2,false) -> #N/A | Q22: =IF('D馬券購入'!B7='仮オッズ'!$B$17,"的中","不的中") -> 不的中
A23: ６列目 | B23: =IFS('D馬券購入'!A6="単勝",$M$22,'D馬券購入'!A6="複勝",$M$23,'D馬券購入'!A6="三連単",$M$24,'D馬券購入'!A6="三連複",$M$25) -> #N/A | C23: =IF(B23<1.1,1.1,B23) -> #N/A | D23: =IFERROR(C23,"未選択") -> 未選択 | F23: 複勝 | G23: =VLOOKUP('D馬券購入'!$B$4,'④の計算式'!複勝,2,false) -> #N/A | H23: =IF(OR('D馬券購入'!B4='仮オッズ'!$B$17,'D馬券購入'!B4='仮オッズ'!$B$18,'D馬券購入'!B4='仮オッズ'!$B$19),"的中","不的中") -> 不的中 | I23: 複勝 | J23: =VLOOKUP('D馬券購入'!$B$5,'④の計算式'!複勝,2,false) -> #N/A | K23: =IF(OR('D馬券購入'!B5='仮オッズ'!$B$17,'D馬券購入'!B5='仮オッズ'!$B$18,'D馬券購入'!B5='仮オッズ'!$B$19),"的中","不的中") -> 不的中 | L23: 複勝 | M23: =VLOOKUP('D馬券購入'!$B$6,'④の計算式'!複勝,2,false) -> #N/A | N23: =IF(OR('D馬券購入'!B6='仮オッズ'!$B$17,'D馬券購入'!B6='仮オッズ'!$B$18,'D馬券購入'!B6='仮オッズ'!$B$19),"的中","不的中") -> 不的中 | O23: 複勝 | P23: =VLOOKUP('D馬券購入'!$B$7,'④の計算式'!複勝,2,false) -> #N/A | Q23: =IF(OR('D馬券購入'!B7='仮オッズ'!$B$17,'D馬券購入'!B7='仮オッズ'!$B$18,'D馬券購入'!B7='仮オッズ'!$B$19),"的中","不的中") -> 不的中
A24: 7列目 | B24: =IFS('D馬券購入'!A7="単勝",$P$22,'D馬券購入'!A7="複勝",$P$23,'D馬券購入'!A7="三連単",$P$24,'D馬券購入'!A7="三連複",$P$25) -> #N/A | C24: =IF(B24<1.1,1.1,B24) -> #N/A | D24: =IFERROR(C24,"未選択") -> 未選択 | F24: 三連単 | G24: =1/((F14*(G14/(1-F14))*(H14/(1-F14-G14)))) -> #N/A | H24: =if(AND('D馬券購入'!B4='仮オッズ'!$B$17,'D馬券購入'!C4='仮オッズ'!$B$18,'D馬券購入'!D4='仮オッズ'!$B$19),"的中","不的中") -> 不的中 | I24: 三連単 | J24: =1/((F15*(G15/(1-F15))*(H15/(1-F15-G15)))) -> #N/A | K24: =if(AND('D馬券購入'!B5='仮オッズ'!$B$17,'D馬券購入'!C5='仮オッズ'!$B$18,'D馬券購入'!D5='仮オッズ'!$B$19),"的中","不的中") -> 不的中 | L24: 三連単 | M24: =1/((F16*(G16/(1-F16))*(H16/(1-F16-G16)))) -> #N/A | N24: =if(AND('D馬券購入'!B6='仮オッズ'!$B$17,'D馬券購入'!C6='仮オッズ'!$B$18,'D馬券購入'!D6='仮オッズ'!$B$19),"的中","不的中") -> 不的中 | O24: 三連単 | P24: =1/((F17*(G17/(1-F17))*(H17/(1-F17-G17)))) -> #N/A | Q24: =if(AND('D馬券購入'!B7='仮オッズ'!$B$17,'D馬券購入'!C7='仮オッズ'!$B$18,'D馬券購入'!D7='仮オッズ'!$B$19),"的中","不的中") -> 不的中
F25: 三連複 | G25: =1/(F14*(G14/(1-F14))*(H14/(1-F14-G14))+F14*(H14/(1-F14))*(G14/(1-F14-H14))+G14*(F14/(1-G14))*(H14/(1-F14-G14))+G14*(H14/(1-G14))*(F14/(1-G14-H14))+H14*(F14/(1-H14))*(G14/(1-H14-F14))+H14*(G14/(1-H14))*(F14/(1-G14-F14))) -> #N/A | H25: =IF(AND(OR('仮オッズ'!$B$17='D馬券購入'!B4,'仮オッズ'!$B$18='D馬券購入'!B4,'仮オッズ'!$B$19='D馬券購入'!B4),OR('仮オッズ'!$B$17='D馬券購入'!C4,'仮オッズ'!$B$18='D馬券購入'!C4,'仮オッズ'!$B$19='D馬券購入'!C4),OR('仮オッズ'!$B$17='D馬券購入'!D4,'仮オッズ'!$B$18='D馬券購入'!D4,'仮オッズ'!$B$19='D馬券購入'!D4)),"的中","不的中") -> 不的中 | I25: 三連複 | J25: =1/(F15*(G15*(1-F15))*(H15/(1-F15-G15))+F15*(H15/(1-F15))*(G15/(1-F15-H15))+G15*(F15/(1-G15))*(H15/(1-F15-G15))+G15*(H15/(1-G15))*(F15/(1-G15-H15))+H15*(F15/(1-H15))*(G15/(1-H15-F15))+H15*(G15/(1-H15))*(F15/(1-G15-F15))) -> #N/A | K25: =IF(AND(OR('仮オッズ'!$B$17='D馬券購入'!B5,'仮オッズ'!$B$18='D馬券購入'!B5,'仮オッズ'!$B$19='D馬券購入'!B5),OR('仮オッズ'!$B$17='D馬券購入'!C5,'仮オッズ'!$B$18='D馬券購入'!C5,'仮オッズ'!$B$19='D馬券購入'!C5),OR('仮オッズ'!$B$17='D馬券購入'!D5,'仮オッズ'!$B$18='D馬券購入'!D5,'仮オッズ'!$B$19='D馬券購入'!D5)),"的中","不的中") -> 不的中 | L25: 三連複 | M25: =1/(F16*(G16*(1-F16))*(H16/(1-F16-G16))+F16*(H16/(1-F16))*(G16/(1-F16-H16))+G16*(F16/(1-G16))*(H16/(1-F16-G16))+G16*(H16/(1-G16))*(F16/(1-G16-H16))+H16*(F16/(1-H16))*(G16/(1-H16-F16))+H16*(G16/(1-H16))*(F16/(1-G16-F16))) -> #N/A | N25: =IF(AND(OR('仮オッズ'!$B$17='D馬券購入'!B6,'仮オッズ'!$B$18='D馬券購入'!B6,'仮オッズ'!$B$19='D馬券購入'!B6),OR('仮オッズ'!$B$17='D馬券購入'!C6,'仮オッズ'!$B$18='D馬券購入'!C6,'仮オッズ'!$B$19='D馬券購入'!C6),OR('仮オッズ'!$B$17='D馬券購入'!D6,'仮オッズ'!$B$18='D馬券購入'!D6,'仮オッズ'!$B$19='D馬券購入'!D6)),"的中","不的中") -> 不的中 | O25: 三連複 | P25: =1/(F17*(G17*(1-F17))*(H17/(1-F17-G17))+F17*(H17/(1-F17))*(G17/(1-F17-H17))+G17*(F17/(1-G17))*(H17/(1-F17-G17))+G17*(H17/(1-G17))*(F17/(1-G17-H17))+H17*(F17/(1-H17))*(G17/(1-H17-F17))+H17*(G17/(1-H17))*(F17/(1-G17-F17))) -> #N/A | Q25: =IF(AND(OR('仮オッズ'!$B$17='D馬券購入'!B7,'仮オッズ'!$B$18='D馬券購入'!B7,'仮オッズ'!$B$19='D馬券購入'!B7),OR('仮オッズ'!$B$17='D馬券購入'!C7,'仮オッズ'!$B$18='D馬券購入'!C7,'仮オッズ'!$B$19='D馬券購入'!C7),OR('仮オッズ'!$B$17='D馬券購入'!D7,'仮オッズ'!$B$18='D馬券購入'!D7,'仮オッズ'!$B$19='D馬券購入'!D7)),"的中","不的中") -> 不的中
B27: ３列目
B28: 単勝の時 | C28: =IF('D馬券購入'!B3='仮オッズ'!$B$17,"的中","不的中") -> 不的中
B29: 三連単の時 | C29: =if(AND('D馬券購入'!B3='仮オッズ'!$B$17,'D馬券購入'!C3='仮オッズ'!$B$18,'D馬券購入'!D3='仮オッズ'!$B$19),"的中","不的中") -> 不的中
B30: 複勝のとき | C30: =IF(OR('D馬券購入'!B3='仮オッズ'!$B$17,'D馬券購入'!B3='仮オッズ'!$B$18,'D馬券購入'!B3='仮オッズ'!$B$19),"的中","不的中") -> 不的中
B31: 三連複のとき | C31: =IF(AND(OR('仮オッズ'!$B$17='D馬券購入'!B3,'仮オッズ'!$B$18='D馬券購入'!B3,'仮オッズ'!$B$19='D馬券購入'!B3),OR('仮オッズ'!$B$17='D馬券購入'!C3,'仮オッズ'!$B$18='D馬券購入'!C3,'仮オッズ'!$B$19='D馬券購入'!C3),OR('仮オッズ'!$B$17='D馬券購入'!D3,'仮オッズ'!$B$18='D馬券購入'!D3,'仮オッズ'!$B$19='D馬券購入'!D3)),"的中","不的中") -> 不的中
B34: 表示する値 | C34: 当選金額 | F34: 合計金額
A35: 3列目 | B35: =IFS('D馬券購入'!A3="単勝",$C$28,'D馬券購入'!A3="三連単",$C$29,'D馬券購入'!A3="複勝",$C$30,'D馬券購入'!A3="三連複",$C$31,'D馬券購入'!A3="未選択","×") -> 不的中 | C35: =IFS(B35="的中",'D馬券購入'!E3*'D馬券購入'!F3,B35="不的中",0,B35="×",0) -> 0 | F35: =CEILING(SUM(C35:C39),5) -> 0
A36: 4列目 | B36: =IFS('D馬券購入'!A4="単勝",$H$22,'D馬券購入'!A4="三連単",$H$24,'D馬券購入'!A4="複勝",$H$23,'D馬券購入'!A4="三連複",$H$25,'D馬券購入'!A4="未選択","×") -> × | C36: =IFS(B36="的中",'D馬券購入'!E4*'D馬券購入'!F4,B36="不的中",0,B36="×",0) -> 0
A37: 5列目 | B37: =IFS('D馬券購入'!A5="単勝",$K$22,'D馬券購入'!A5="三連単",$K$24,'D馬券購入'!A5="複勝",$K$23,'D馬券購入'!A5="三連複",$K$25,'D馬券購入'!A5="未選択","×") -> × | C37: =IFS(B37="的中",'D馬券購入'!E5*'D馬券購入'!F5,B37="不的中",0,B37="×",0) -> 0
A38: ６列目 | B38: =IFS('D馬券購入'!A6="単勝",$N$22,'D馬券購入'!A6="三連単",$N$24,'D馬券購入'!A6="複勝",$N$23,'D馬券購入'!A6="三連複",$N$25,'D馬券購入'!A6="未選択","×") -> × | C38: =IFS(B38="的中",'D馬券購入'!E6*'D馬券購入'!F6,B38="不的中",0,B38="×",0) -> 0
A39: 7列目 | B39: =IFS('D馬券購入'!A7="単勝",$Q$22,'D馬券購入'!A7="三連単",$Q$24,'D馬券購入'!A7="複勝",$Q$23,'D馬券購入'!A7="三連複",$Q$25,'D馬券購入'!A7="未選択","×") -> × | C39: =IFS(B39="的中",'D馬券購入'!E7*'D馬券購入'!F7,B39="不的中",0,B39="×",0) -> 0

Sheet D馬券購入
A2: 券種 | B2: 賭ける人 | E2: 賭けPt | F2: オッズ | G2: 的・不的 | H2: 合計賭け金
A3: 複勝 | B3: いずみ | C3: 未選択 | D3: 未選択 | E3: 2220 | F3: ='④の計算式'!D20 -> 13.672292 | G3: =IF(COUNTIF('仮オッズ'!$A$17:$B$22,"未選択")>0,"×",'④の計算式'!B35) -> 不的中 | H3: =SUM(E3:E7) -> 2220
A4: 未選択 | B4: 未選択 | C4: 未選択 | D4: 未選択 | E4: 0 | F4: ='④の計算式'!D21 -> 未選択 | G4: =IF(COUNTIF('仮オッズ'!$A$17:$B$22,"未選択")>0,"×",'④の計算式'!B36) -> × | H4: 払い戻し金
A5: 未選択 | B5: 未選択 | C5: 未選択 | D5: 未選択 | F5: ='④の計算式'!D22 -> 未選択 | G5: =IF(COUNTIF('仮オッズ'!$A$17:$B$22,"未選択")>0,"×",'④の計算式'!B37) -> × | H5: =IF(COUNTIF('仮オッズ'!$B$17:$B$22,"未選択")>0,"×",'④の計算式'!F35) -> 0
A6: 未選択 | B6: 未選択 | C6: 未選択 | D6: 未選択 | F6: ='④の計算式'!D23 -> 未選択 | G6: =IF(COUNTIF('仮オッズ'!$A$17:$B$22,"未選択")>0,"×",'④の計算式'!B38) -> × | H6: 収支
A7: 未選択 | B7: 未選択 | C7: 未選択 | D7: 未選択 | F7: ='④の計算式'!D24 -> 未選択 | G7: =IF(COUNTIF('仮オッズ'!$A$17:$B$22,"未選択")>0,"×",'④の計算式'!B39) -> × | H7: =IF(H5="×","×",H5-H3) -> -2220

Sheet ⑤の計算式
I1: xが1着になる確率
B2: 単勝 | E2: 複勝 | H2: 三連 | I2: p(x)
B3: ='仮オッズ'!A2 -> ゆーや | C3: ='仮オッズ'!D2 -> 2.1052632 | E3: ='仮オッズ'!A2 -> ゆーや | F3: =1/(1-(1-(1/'仮オッズ'!D2))^3) -> 1.1691847 | H3: ='仮オッズ'!A2 -> ゆーや | I3: =1/C3 -> 0.475
B4: ='仮オッズ'!A3 -> たいよう | C4: ='仮オッズ'!D3 -> 2.3529412 | E4: ='仮オッズ'!A3 -> たいよう | F4: =1/(1-(1-(1/'仮オッズ'!D3))^3) -> 1.2347346 | H4: ='仮オッズ'!A3 -> たいよう | I4: =1/C4 -> 0.425
B5: ='仮オッズ'!A4 -> はせりょー | C5: ='仮オッズ'!D4 -> 5.7142857 | E5: ='仮オッズ'!A4 -> はせりょー | F5: =1/(1-(1-(1/'仮オッズ'!D4))^3) -> 2.280583 | H5: ='仮オッズ'!A4 -> はせりょー | I5: =1/C5 -> 0.175
B6: ='仮オッズ'!A5 -> みわ | C6: ='仮オッズ'!D5 -> 13.333333 | E6: ='仮オッズ'!A5 -> みわ | F6: =1/(1-(1-(1/'仮オッズ'!D5))^3) -> 4.795085 | H6: ='仮オッズ'!A5 -> みわ | I6: =1/C6 -> 0.075
B7: ='仮オッズ'!A6 -> こーた | C7: ='仮オッズ'!D6 -> 13.333333 | E7: ='仮オッズ'!A6 -> こーた | F7: =1/(1-(1-(1/'仮オッズ'!D6))^3) -> 4.795085 | H7: ='仮オッズ'!A6 -> こーた | I7: =1/C7 -> 0.075
B8: ='仮オッズ'!A7 -> いずみ | C8: ='仮オッズ'!D7 -> 40 | E8: ='仮オッズ'!A7 -> いずみ | F8: =1/(1-(1-(1/'仮オッズ'!D7))^3) -> 13.672292 | H8: ='仮オッズ'!A7 -> いずみ | I8: =1/C8 -> 0.025
B9: ='仮オッズ'!A8 -> 未選択 | C9: ='仮オッズ'!D8 | E9: ='仮オッズ'!A8 -> 未選択 | H9: ='仮オッズ'!A8 -> 未選択
B10: ='仮オッズ'!A9 | C10: ='仮オッズ'!D9:D18 | E10: ='仮オッズ'!A9 | H10: ='仮オッズ'!A9
B11: ='仮オッズ'!A10 | E11: ='仮オッズ'!A10 | H11: ='仮オッズ'!A10
B12: 3列目 | F12: 三連
F13: =IFS('E馬券購入'!B3='仮オッズ'!$A$2,$I$3,'E馬券購入'!B3='仮オッズ'!$A$3,$I$4,'E馬券購入'!B3='仮オッズ'!$A$4,$I$5,'E馬券購入'!B3='仮オッズ'!$A$5,$I$6,'E馬券購入'!B3='仮オッズ'!$A$6,$I$7,'E馬券購入'!B3='仮オッズ'!$A$7,$I$8) -> 0.475 | G13: =IFS('E馬券購入'!C3='仮オッズ'!$A$2,$I$3,'E馬券購入'!C3='仮オッズ'!$A$3,$I$4,'E馬券購入'!C3='仮オッズ'!$A$4,$I$5,'E馬券購入'!C3='仮オッズ'!$A$5,$I$6,'E馬券購入'!C3='仮オッズ'!$A$6,$I$7,'E馬券購入'!C3='仮オッズ'!$A$7,$I$8) -> 0.175 | H13: =IFS('E馬券購入'!D3='仮オッズ'!$A$2,$I$3,'E馬券購入'!D3='仮オッズ'!$A$3,$I$4,'E馬券購入'!D3='仮オッズ'!$A$4,$I$5,'E馬券購入'!D3='仮オッズ'!$A$5,$I$6,'E馬券購入'!D3='仮オッズ'!$A$6,$I$7,'E馬券購入'!D3='仮オッズ'!$A$7,$I$8) -> 0.075
A14: 単勝 | B14: =VLOOKUP('E馬券購入'!B$3,'⑤の計算式'!単勝,2,false) -> 2.1052632 | F14: =IFS('E馬券購入'!B4='仮オッズ'!$A$2,$I$3,'E馬券購入'!B4='仮オッズ'!$A$3,$I$4,'E馬券購入'!B4='仮オッズ'!$A$4,$I$5,'E馬券購入'!B4='仮オッズ'!$A$5,$I$6,'E馬券購入'!B4='仮オッズ'!$A$6,$I$7,'E馬券購入'!B4='仮オッズ'!$A$7,$I$8) -> 0.025 | G14: =IFS('E馬券購入'!C4='仮オッズ'!$A$2,$I$3,'E馬券購入'!C4='仮オッズ'!$A$3,$I$4,'E馬券購入'!C4='仮オッズ'!$A$4,$I$5,'E馬券購入'!C4='仮オッズ'!$A$5,$I$6,'E馬券購入'!C4='仮オッズ'!$A$6,$I$7,'E馬券購入'!C4='仮オッズ'!$A$7,$I$8) -> #N/A | H14: =IFS('E馬券購入'!D4='仮オッズ'!$A$2,$I$3,'E馬券購入'!D4='仮オッズ'!$A$3,$I$4,'E馬券購入'!D4='仮オッズ'!$A$4,$I$5,'E馬券購入'!D4='仮オッズ'!$A$5,$I$6,'E馬券購入'!D4='仮オッズ'!$A$6,$I$7,'E馬券購入'!D4='仮オッズ'!$A$7,$I$8) -> #N/A
A15: 複勝 | B15: =VLOOKUP('E馬券購入'!B3,'⑤の計算式'!複勝,2,false) -> 1.1691847 | F15: =IFS('E馬券購入'!B5='仮オッズ'!$A$2,$I$3,'E馬券購入'!B5='仮オッズ'!$A$3,$I$4,'E馬券購入'!B5='仮オッズ'!$A$4,$I$5,'E馬券購入'!B5='仮オッズ'!$A$5,$I$6,'E馬券購入'!B5='仮オッズ'!$A$6,$I$7,'E馬券購入'!B5='仮オッズ'!$A$7,$I$8) -> 0.075 | G15: =IFS('E馬券購入'!C5='仮オッズ'!$A$2,$I$3,'E馬券購入'!C5='仮オッズ'!$A$3,$I$4,'E馬券購入'!C5='仮オッズ'!$A$4,$I$5,'E馬券購入'!C5='仮オッズ'!$A$5,$I$6,'E馬券購入'!C5='仮オッズ'!$A$6,$I$7,'E馬券購入'!C5='仮オッズ'!$A$7,$I$8) -> 0.075 | H15: =IFS('E馬券購入'!D5='仮オッズ'!$A$2,$I$3,'E馬券購入'!D5='仮オッズ'!$A$3,$I$4,'E馬券購入'!D5='仮オッズ'!$A$4,$I$5,'E馬券購入'!D5='仮オッズ'!$A$5,$I$6,'E馬券購入'!D5='仮オッズ'!$A$6,$I$7,'E馬券購入'!D5='仮オッズ'!$A$7,$I$8) -> 0.025
A16: 三連単 | B16: =1/((F13*(G13/(1-F13))*(H13/(1-F13-G13)))) -> 29.473684 | F16: =IFS('E馬券購入'!B6='仮オッズ'!$A$2,$I$3,'E馬券購入'!B6='仮オッズ'!$A$3,$I$4,'E馬券購入'!B6='仮オッズ'!$A$4,$I$5,'E馬券購入'!B6='仮オッズ'!$A$5,$I$6,'E馬券購入'!B6='仮オッズ'!$A$6,$I$7,'E馬券購入'!B6='仮オッズ'!$A$7,$I$8) -> 0.075 | G16: =IFS('E馬券購入'!C6='仮オッズ'!$A$2,$I$3,'E馬券購入'!C6='仮オッズ'!$A$3,$I$4,'E馬券購入'!C6='仮オッズ'!$A$4,$I$5,'E馬券購入'!C6='仮オッズ'!$A$5,$I$6,'E馬券購入'!C6='仮オッズ'!$A$6,$I$7,'E馬券購入'!C6='仮オッズ'!$A$7,$I$8) -> #N/A | H16: =IFS('E馬券購入'!D6='仮オッズ'!$A$2,$I$3,'E馬券購入'!D6='仮オッズ'!$A$3,$I$4,'E馬券購入'!D6='仮オッズ'!$A$4,$I$5,'E馬券購入'!D6='仮オッズ'!$A$5,$I$6,'E馬券購入'!D6='仮オッズ'!$A$6,$I$7,'E馬券購入'!D6='仮オッズ'!$A$7,$I$8) -> #N/A
A17: 三連複 | B17: =1/(F13*(G13/(1-F13))*(H13/(1-F13-G13))+F13*(H13/(1-F13))*(G13/(1-F13-H13))+G13*(F13/(1-G13))*(H13/(1-F13-G13))+G13*(H13/(1-G13))*(F13/(1-G13-H13))+H13*(F13/(1-H13))*(G13/(1-H13-F13))+H13*(G13/(1-H13))*(F13/(1-G13-F13))) -> 7.9227776 | F17: =IFS('E馬券購入'!B7='仮オッズ'!$A$2,$I$3,'E馬券購入'!B7='仮オッズ'!$A$3,$I$4,'E馬券購入'!B7='仮オッズ'!$A$4,$I$5,'E馬券購入'!B7='仮オッズ'!$A$5,$I$6,'E馬券購入'!B7='仮オッズ'!$A$6,$I$7,'E馬券購入'!B7='仮オッズ'!$A$7,$I$8) -> 0.075 | G17: =IFS('E馬券購入'!C7='仮オッズ'!$A$2,$I$3,'E馬券購入'!C7='仮オッズ'!$A$3,$I$4,'E馬券購入'!C7='仮オッズ'!$A$4,$I$5,'E馬券購入'!C7='仮オッズ'!$A$5,$I$6,'E馬券購入'!C7='仮オッズ'!$A$6,$I$7,'E馬券購入'!C7='仮オッズ'!$A$7,$I$8) -> #N/A | H17: =IFS('E馬券購入'!D7='仮オッズ'!$A$2,$I$3,'E馬券購入'!D7='仮オッズ'!$A$3,$I$4,'E馬券購入'!D7='仮オッズ'!$A$4,$I$5,'E馬券購入'!D7='仮オッズ'!$A$5,$I$6,'E馬券購入'!D7='仮オッズ'!$A$6,$I$7,'E馬券購入'!D7='仮オッズ'!$A$7,$I$8) -> #N/A
F18: =IFS('E馬券購入'!B8='仮オッズ'!$A$2,$I$3,'E馬券購入'!B8='仮オッズ'!$A$3,$I$4,'E馬券購入'!B8='仮オッズ'!$A$4,$I$5,'E馬券購入'!B8='仮オッズ'!$A$5,$I$6,'E馬券購入'!B8='仮オッズ'!$A$6,$I$7,'E馬券購入'!B8='仮オッズ'!$A$7,$I$8) -> #N/A | G18: =IFS('E馬券購入'!C8='仮オッズ'!$A$2,$I$3,'E馬券購入'!C8='仮オッズ'!$A$3,$I$4,'E馬券購入'!C8='仮オッズ'!$A$4,$I$5,'E馬券購入'!C8='仮オッズ'!$A$5,$I$6,'E馬券購入'!C8='仮オッズ'!$A$6,$I$7,'E馬券購入'!C8='仮オッズ'!$A$7,$I$8) -> #N/A | H18: =IFS('E馬券購入'!D8='仮オッズ'!$A$2,$I$3,'E馬券購入'!D8='仮オッズ'!$A$3,$I$4,'E馬券購入'!D8='仮オッズ'!$A$4,$I$5,'E馬券購入'!D8='仮オッズ'!$A$5,$I$6,'E馬券購入'!D8='仮オッズ'!$A$6,$I$7,'E馬券購入'!D8='仮オッズ'!$A$7,$I$8) -> #N/A
